Workbook
Name AsOfDate: '00_前提・使い方'!$B$5
Name EvalIDs: '32_定義マスター'!$A$13:$A$30
Name EvalPlanKeys: '15_評価計画・品質ゲート'!$V$4:$V$103
Name RoleIDs: '06_ロール・要員計画'!$A$4:$A$23
Name SkillIDs: '07_スキル辞書'!$A$4:$A$109
Name TaskIDs: '02_工程タスク'!$A$4:$A$135

Sheet 00_前提・使い方
A1: AIシステム自社事業PJ 工程管理 v1.1
A2: 事業仮説 → 投資 → 利用者価値 → 公開 → 実績 → 継続／撤退｜添付改訂提案を実行用に整理
A3: 項目 | B3: 内容・案件入力 | C3: 運用上の注意
A4: 版 | B4: v1.1（敵対的レビュー27件反映） | C4: v1.0原本を保持した改訂版。132Task／106Skill／20Roleは継承。修正対応と検証は33。
A5: 管理基準日 | B5: 46271 | C5: 期限チェックはこの日付。運用時に更新する。
A6: 事業・サービス名 | C6: 案件開始時に必須入力
A7: 提供形態 | C7: B2B / B2C / 社内事業 / 複合
A8: 対象業界・用途 | C8: 高影響・規制業務を含めて記入
A9: 提供国・利用者所在国 | C9: 日本を自動前提にしない。法令判定12へ接続
A10: 処理・保存・送信国 | C10: 開発AI、評価SaaS、ログ基盤も含む
A11: Business Owner（実名） | C11: R01。投資・継続・撤退の最終責任
A12: Product / Service Owner | C12: R02とR18をそれぞれ記入
A13: 機能・モデル・配置 | C13: 非AI比較、RAG、Agent、学習、API/ローカル
A14: 主要データ・権利 | C14: 個人情報区分、利用目的、取扱いOwner
A15: Risk Tier（確定値） | C15: 03で判定し人が承認。T0〜T3は社内分類
A16: 規模・予算・期間 | C16: 小中大、概算予算、探索上限、対象期間
A17: 既存統合・利用者・SLO | C17: 容量、重要度、統合件数、サービス時間
... A19: 記録の正本 | C19: 仕様・コード・評価・承認の実際の保存先
A20: 使い始めの順序 | B20: 00 → 03/04 → 05/06/35 → 25/26 → 15/17 → 16/30 → 29/31 → 20 | C20: 最初に前提と意思決定者を埋める。全タスクの機械的実施は不要。
A21: 資料の責務 | B21: 02=標準定義、17=実行原票、15/16=評価、29=承認、25/26=事業仮説・投資 | C21: Excelは索引・点検。仕様／コード／評価／決裁は版管理された正本。Run・同期は34。
A22: 七工程 | B22: 企画→要件→設計→実装↔評価→運用→廃止 | C22: 順番の固定ではなく反復モデル。評価計画は要件で開始する。
A23: PoCの扱い | B23: 最大の不確実性を潰す最小実験 | C23: 独立した必須工程にはしない。失敗・停止も正当な成果。
A24: 色と入力 | B24: 薄黄＋青字=案件入力、濃色見出し=定義、黒字数式=自動計算 | C24: 値0と未測定の空欄を区別。数式セルは上書きしない。
A25: 習熟度 | B25: Lv0=関与なし、Lv1=指導下、Lv2=自律遂行、Lv3=設計・指導・例外判断 | C25: 人の能力は07/28、AgentのSkillパッケージは14/11で別管理。
A26: 根拠の扱い | B26: U01=添付提案、U02=受託版、U03=本資料で具体化、W*=一次資料再確認 | C26: 原文のレンジ・目標は参考。法令・任意指針・実践例を24で区別。
A27: 案件未確定 | B27: 実名、日時、金額、評価閾値、法適用、承認は未入力 | C27: テンプレートに完了承認済みの架空データは置いていない。
A28: 自動チェックの限界 | B28: 記録・参照・日時・定義整合を点検。真正な決裁・法令適合・実行権限・証拠内容は正本側で確認。 | C28: 実質的な品質、法令適合、URIの実在、循環依存、クリティカルパスは人が確認。
A29: 更新・反復 | B29: 17は初回132行。反復34、計画15・実績16・Gate29は予約行へ追加。上限外は正本管理とテンプレート改訂。 | C29: 検証スクリプトは循環・未知ID・数値・ID重複・同期仕様を補助検査。Excelの直接依存点検とは別。
A30: 重要な停止原則 | B30: 法的禁止、未承認の実データ送信、重大未対策、独立評価不合格は公開しない | C30: 事業責任者の予算承認で法務・安全の不合格を上書きしない。
A34: 記録ダッシュボード（品質・事業成果の合否ではありません）
A35: 指標 | B35: 自動集計 | C35: 意味
A36: 標準タスク数 | B36: =COUNTA('02_工程タスク'!A4:A135) -> 132 | C36: 初回ライフサイクルの定義数
A37: スキル数 | B37: =COUNTA('07_スキル辞書'!A4:A109) -> 106 | C37: 行動基準を持つ人の能力辞書
A38: 適用未判定 | B38: =COUNTIF('17_ロードマップ・案件実行管理'!E4:E135,"未判定") -> 132 | C38: 人による適用判定が必要な数
A39: 適用タスク | B39: =COUNTIF('17_ロードマップ・案件実行管理'!E4:E135,"適用") -> 0 | C39: 対象外は別承認が必要
A40: 完了記録・前提充足 | B40: =SUM('17_ロードマップ・案件実行管理'!AA4:AA135) -> 0 | C40: 証跡の内容まで自動審査しない
A41: 完了記録率 | B41: =IF(B39=0,"",B40/B39) | C41: 適用タスクに対する記録上の完了率
A42: 予定人時間 | B42: =IF(COUNT('17_ロードマップ・案件実行管理'!P4:P135)=0,"",SUM('17_ロードマップ・案件実行管理'!P4:P135)) | C42: 未入力を実績0と表示しない
A45: シートナビゲーション
A46: シート | B46: 役割 | C46: 推奨利用時点
...

Sheet 01_事業ライフサイクル・ゲート
A1: 事業ライフサイクルと投資・公開ゲート
A2: 七工程は反復・並行可能。契約は23へ分離。品質・法令の不合格を投資承認で上書きしない。
A3: ID | B3: 工程 | C3: 目的 | D3: 開始・前提 | E3: Gate | F3: 最終A | G3: 必要な証拠 | H3: 判断・戻り先 | I3: 根拠
A4: B0 | B4: 企画 | C4: 利用者課題・非AI比較・需要・採算・データ・リスクを検証 | D4: B0-01で限定探索枠を先に承認 | E4: G0 | F4: R01 | G4: Opportunity Brief、反証、Business Case、体制 | H4: 次の探索・要件投資を限定承認。需要不成立は停止 | I4: U01,U03
A5: B1 | B5: 要件 | C5: 価値・業務・AI境界・評価・データ・SLOを定義 | D5: G0。ただしデータ利用承認は実取得より前 | E5: G1 | F5: R01 | G5: Product Spec、Eval Plan、Privacy、予算・体制 | H5: スコープ・証拠計画承認。必要に応じ企画へ戻す | I5: U01,U03
A6: B2 | B6: 設計 | C6: 方式・データ・権限・UX・Harness・復旧・原価を設計 | D6: G1・必要な利用/外部送信条件 | E6: G2 | F6: R01 | G6: ADR、Threat Model、権限、運用、費用 | H6: 技術責任者の勧告＋次のBuild投資承認 | I6: U01,U03
A7: B3 | B7: 実装 | C7: 小さな縦切りで実装・自動検証・レビューを反復 | D7: G2。小変更は承認済み境界内で継続 | E7: G3への入力 | F7: R06 | G7: コード/構成manifest、CI、評価、PR | H7: 固定RCへ。評価を後工程へ先送りしない | I7: U01,U03
A8: B4 | B8: 評価 | C8: 独立品質・安全・運用評価→段階公開→Launch | D8: 固定RC。公開前にG3 | E8: G3 | F8: R18 | G8: 独立評価、Privacy/Security、運用、採算、停止 | H8: R19が品質判定。重大リスク受容はR01。公開後も監視 | I8: U01,U03
A9: B5 | B9: 運用 | C9: 価値・品質・SLO・費用を観測し実験・改善 | D9: G3・運用引継ぎ | E9: G4 | F9: R01 | G9: 事業KPI、継続率、原価、事故、変更、投資 | H9: Scale / Continue / Pivot / Shrink / Stop | I9: U01,U03
A10: B6 | B10: 廃止 | C10: 通知・移行・データ・権限・契約・費用を終了 | D10: 任意GateのStop／承認済み廃止判断。G3/G4未到達でも可。 | E10: G5 | F10: R01 | G10: Deletion/Retention、失効試験、解約、独立確認 | H10: 保全残件は期限付きOwnerへ。画面閉鎖だけで完了しない | I10: U01,U03
A13: ゲートに共通する判断ルール
A14: 観点 | B14: 定義 | C14: 必要な記録 | D14: 禁止事項 | E14: 関連シート
A15: Go | B15: 承認した範囲・版・予算のみ進行 | C15: 承認した範囲・版・予算のみ。条件は31のConditionIDで所有者・期限・解消・失効を追跡。 | D15: 全額投資・用途拡大の白紙委任 | E15: 29
A16: 条件付き | B16: 安全・法令の必須条件を満たす範囲に限定 | C16: 条件、Owner、期限、期限切れ時停止 | D16: 重大未対策や違法行為を条件付きで承認 | E16: 19,29
A17: 再検証 / Pivot | B17: 仮説と実験計画を改訂 | C17: 反証、追加費用、停止期限 | D17: 成功例だけを残す | E17: 25,26
A18: Stop / Shrink | B18: 新規公開を制限し縮小・廃止へ | C18: 利用者保護、移行、残件 | D18: 画面を閉じるだけで終了 | E18: 22
A19: 緊急変更 | B19: 被害抑止のための限定措置 | C19: 権限者、時刻、実施内容、事後審査期限 | D19: 恒久変更を緊急扱いで放置 | E19: 20,21

Sheet 02_工程タスク
A1: 工程タスク｜標準定義の正本
A2: 132タスク。S/M/Lで安全工程を自動省略しない。適用・実名・期限・証拠は17に記録。B-IDは自社事業版の独立ID。
A3: タスクID | B3: 工程 | C3: 作業区分 | D3: タスク名 | E3: 具体的な実施内容 | F3: 成果物・証拠群 | G3: 実施R | H3: 承認A | I3: 完了条件 | J3: 適用条件 | K3: S | L3: M | M3: L | N3: Gate | O3: 基本依存ID | P3: 必要スキルID | Q3: AI活用と人の境界 | R3: 旧v3 ID | S3: 記載区分 | T3: 根拠ID | U3: 確認用URL
A4: B0-01 | B4: 企画 | C4: 探索統制 | D4: 探索責任者・初期枠の設定 | E4: 誰が事業価値と損失に責任を持つかを確定し、G0以前の探索に使える人時間・費用・期間を限定する。公開情報調査を原則とし、未承認の実データ取得を禁止する。 | F4: 探索チャーター・初期予算枠 | G4: R02, R03 | H4: R01 | I4: 責任者、探索上限、意思決定日、停止権限が記録されている。 | J4: 全 | K4: 共通 | L4: 共通 | M4: 共通 | N4: G0 | P4: S001,S006,S082 | Q4: AIで調査・仮説・質問を草案化。人が一次情報・実行動・投資判断を確認。 | R4: P0-06,P1-03 | S4: 添付提案の具体化／旧版再編 | T4: U01,U02
A5: B0-02 | B5: 企画 | C5: 市場調査 | D5: 市場・競合・規制候補の調査 | E5: 市場、代替サービス、既存業務、対象国と規制業種を一次情報で確認する。AIで草案化しても事実・推定・未確認を分離する。 | F5: 調査メモ・根拠一覧 | G5: R02, R04, R16 | H5: R02 | I5: 対象市場、利用者、競合、情報の確認日と不確実性がある。 | J5: 全 | K5: 共通 | L5: 共通 | M5: 共通 | N5: G0 | O5: B0-01 | P5: S002,S007,S008 | Q5: AIで調査・仮説・質問を草案化。人が一次情報・実行動・投資判断を確認。 | R5: P0-01 | S5: 添付提案の具体化／旧版再編 | T5: U01,W01 | U5: https://www.meti.go.jp/shingikai/mono_info_service/ai_shakai_jisso/
A6: B0-03 | B6: 企画 | C6: 課題探索 | D6: 利用者・購買者の仮説分解 | E6: B2Bは利用者・決裁者・管理者、B2Cは利用者・支払者を区別し、社内利用は受益部門を特定する。調査参加同意と記録の扱いを決める。 | F6: 対象セグメント・調査計画 | G6: R02, R05 | H6: R02 | I6: 対象者、募集条件、質問、個人情報取扱いが明確。 | J6: 全 | K6: 共通 | L6: 共通 | M6: 共通 | N6: G0 | O6: B0-02 | P6: S004,S082,S085 | Q6: AIで調査・仮説・質問を草案化。人が一次情報・実行動・投資判断を確認。 | R6: P0-02 | S6: 添付提案の具体化／旧版再編 | T6: U01
A7: B0-04 | B7: 企画 | C7: 課題探索 | D7: インタビュー・現場観察 | E7: 現行行動、困りごとの頻度・損失、回避策を調べる。AIへの期待だけを需要の証拠にせず、発言と実行行動を分ける。 | F7: JTBD・観察記録 | G7: R05, R04 | H7: R02 | I7: 現行の代替行動と未解決課題を記録し、反証も保存。 | J7: 全 | K7: 共通 | L7: 共通 | M7: 共通 | N7: G0 | O7: B0-03 | P7: S004,S019,S082 | Q7: AIで調査・仮説・質問を草案化。人が一次情報・実行動・投資判断を確認。 | R7: P0-03,P1-01 | S7: 添付提案の具体化／旧版再編 | T7: U01
A8: B0-05 | B8: 企画 | C8: 価値仮説 | D8: 課題・価値・差別化の定義 | E8: 誰のどの業務成果をどれだけ改善するかを定義する。AI搭載自体を価値とせず、解決しない問題と競争優位の仮説を明記する。 | F8: Opportunity Brief | G8: R02, R04 | H8: R01 | I8: 価値仮説、非対象、代替手段との違いを説明できる。 | J8: 全 | K8: 共通 | L8: 共通 | M8: 共通 | N8: G0 | O8: B0-04 | P8: S008,S009,S082 | Q8: AIで調査・仮説・質問を草案化。人が一次情報・実行動・投資判断を確認。 | R8: P1-02 | S8: 添付提案の具体化／旧版再編 | T8: U01
A9: B0-06 | B9: 企画 | C9: 方式探索 | D9: 非AI・Build/Buy/Partnerの比較 | E9: 業務変更、ルール、既製SaaS、モデルAPI、RAG、学習、自律Agentを比較する。最も単純に価値を満たす案から試す。 | F9: 方式比較・仮ADR | G9: R06, R08, R20 | H9: R01 | I9: 品質、運用責任、権利、総費用、切替可能性を比較。 | J9: 全 | K9: 共通 | L9: 共通 | M9: 共通 | N9: G0 | O9: B0-05 | P9: S018,S030,S053,S054 | Q9: AIで調査・仮説・質問を草案化。人が一次情報・実行動・投資判断を確認。 | R9: P0-04,P1-04 | S9: 添付提案の具体化／旧版再編 | T9: U01,W04 | U9: https://www.anthropic.com/engineering/building-effective-agents
A10: B0-07 | B10: 企画 | C10: データ戦略 | D10: データ資産・権利の棚卸し | E10: 所在、Owner、利用権、品質、取得費、更新性をメタデータから把握する。サンプル取得は利用可否承認後に行う。 | F10: 初期Data Asset候補 | G10: R09, R10, R14 | H10: R10 | I10: 必要データと不足、権利未確認部分、取得計画がある。 | J10: 全 | K10: 共通 | L10: 共通 | M10: 共通 | N10: G0 | O10: B0-05 | P10: S003,S055,S056 | Q10: AIで調査・仮説・質問を草案化。人が一次情報・実行動・投資判断を確認。 | R10: P1-05,P1-19 | S10: 添付提案の具体化／旧版再編 | T10: U01,W02,W03 | U10: https://www.ppc.go.jp/personalinfo/legal/guidelines_anonymous/ https://www.ppc.go.jp/personalinfo/legal/guidelines_offshore/
A11: B0-08 | B11: 企画 | C11: リスク | D11: 製品AI・開発AIの初期リスク分類 | E11: 危害、データ、自律度、書込み、対象者、国を確認する。T0〜T3は社内区分であり法的分類とは分離する。 | F11: 初期Risk Tier・法令スコープ | G11: R02, R13, R14, R11 | H11: R01 | I11: 製品と開発Agentを別境界で評価し未確定条件を記録。 | J11: 全 | K11: 共通 | L11: 共通 | M11: 共通 | N11: G0 | O11: B0-06,B0-07 | P11: S002,S017,S078 | Q11: AIで調査・仮説・質問を草案化。人が一次情報・実行動・投資判断を確認。 | R11: P1-07 | S11: 添付提案の具体化／旧版再編 | T11: U01,W01,W10 | U11: https://www.meti.go.jp/shingikai/mono_info_service/ai_shakai_jisso/ https://www.nist.gov/publications/artificial-intelligence-risk-management-framework-generative-artificial-intelligence
A12: B0-09 | B12: 企画 | C12: 収益仮説 | D12: 価格・支払意思・提供形態の仮説 | E12: 課金単位、支払意思、無償範囲、利用上限、B2B導入条件を検討する。社内事業は売上でなく内部価値と費用負担を定める。 | F12: 価格仮説・価値交換モデル | G12: R02, R15, R16 | H12: R01 | I12: 誰が何に支払うか、代替価格、検証方法がある。 | J12: 全 | K12: 共通 | L12: 共通 | M12: 共通 | N12: G0 | O12: B0-05 | P12: S083,S084,S093 | Q12: AIで調査・仮説・質問を草案化。人が一次情報・実行動・投資判断を確認。 | R12: P1-17 | S12: 添付提案の具体化／旧版再編 | T12: U01
A13: B0-10 | B13: 企画 | C13: 投資計画 | D13: 単位経済性・TCO・感度分析 | E13: AI費、検索、保存、再試行、人手確認、CS、固定費を分け、成功タスク当たり原価を試算する。利用増・単価変更・低成功率を含むシナリオを置く。 | F13: Business Case・原価仮説 | G13: R15, R08, R12 | H13: R01 | I13: 費用境界と仮定が明確で、AI一律削減を含まない。 | J13: 全 | K13: 共通 | L13: 共通 | M13: 共通 | N13: G0 | O13: B0-06,B0-09 | P13: S010,S012,S050,S093 | Q13: AIで調査・仮説・質問を草案化。人が一次情報・実行動・投資判断を確認。 | R13: P1-06,P2-15 | S13: 添付提案の具体化／旧版再編 | T13: U01,W08 | U13: https://dora.dev/ai/roi/calculator/
A14: B0-11 | B14: 企画 | C14: 実験計画 | D14: 最大不確実性と検証順の設定 | E14: 需要・実現性・安全性・採算の仮説ごとに、反証条件、最小実験、予算・期限を決める。PoCは必要な仮説にのみ置く。 | F14: 仮説・実験バックログ | G14: R02, R08, R11 | H14: R02 | I14: 成功だけでなく再検証・縮小・停止条件が事前定義。 | J14: 全 | K14: 共通 | L14: 共通 | M14: 共通 | N14: G0 | O14: B0-08,B0-10 | P14: S062,S087,S104 | Q14: AIで調査・仮説・質問を草案化。人が一次情報・実行動・投資判断を確認。 | R14: P1-20 | S14: 添付提案の具体化／旧版再編 | T14: U01,W04 | U14: https://www.anthropic.com/engineering/building-effective-agents
A15: B0-12 | B15: 企画 | C15: 需要検証 | D15: コンセプト・手動代替による需要検証 | E15: モックや人手サービスで利用意思と現実の行動を確認する。誤認を招く未実装機能の宣伝や、無承認の高影響用途での試験を避ける。 | F15: 需要検証記録 | G15: R05, R02, R16 | H15: R02 | I15: 募集条件、観察結果、反証、次の判断がある。 | J15: 条件:需要不確実 | K15: 条件 | L15: 条件 | M15: 条件 | N15: G0 | O15: B0-11 | P15: S021,S082,S087 | Q15: AIで調査・仮説・質問を草案化。人が一次情報・実行動・投資判断を確認。 | R15: P2-14 | S15: 添付提案の具体化／旧版再編 | T15: U01
A16: B0-13 | B16: 企画 | C16: 実現性検証 | D16: 限定プロトタイプ・非AIベースライン | E16: 合成・公開・承認済みデータで核心機能だけを試す。RAGは検索、Agentはread-onlyから試し、本番品質と同一視しない。 | F16: 最小実験・ベースライン | G16: R08, R07, R11 | H16: R06 | I16: データ許可、比較条件、限界、再現手順が残る。 | J16: 条件:技術不確実 | K16: 条件 | L16: 条件 | M16: 条件 | N16: G0 | O16: B0-07,B0-08,B0-11 | P16: S033,S062,S068 | Q16: AIで調査・仮説・質問を草案化。人が一次情報・実行動・投資判断を確認。 | R16: P2-02,P2-09,P2-10 | S16: 添付提案の具体化／旧版再編 | T16: U01,W04 | U16: https://www.anthropic.com/engineering/building-effective-agents
A17: B0-14 | B17: 企画 | C17: 事業計画 | D17: 提供・販売・サポート経路の仮設計 | E17: 獲得経路、導入負荷、セキュリティ審査、販売リードタイム、問い合わせ窓口を検討し、営業と運用の費用を含める。 | F17: GTM・導入仮説 | G17: R16, R17, R02 | H17: R01 | I17: 利用開始までの障壁と検証予定を記録。 | J17: 全 | K17: 共通 | L17: 共通 | M17: 共通 | N17: G0 | O17: B0-09 | P17: S085,S086,S089 | Q17: AIで調査・仮説・質問を草案化。人が一次情報・実行動・投資判断を確認。 | R17: P4-21 | S17: 添付提案の具体化／旧版再編 | T17: U01
A18: B0-15 | B18: 企画 | C18: 体制 | D18: ロール・能力ギャップ・要員計画 | E18: 事業責任、PdM、実装、評価、本番、データ、法務の担当を決める。兼務時も自己承認を避け、必要な外部専門家を確保する。 | F18: RACI・スキル充足計画 | G18: R03, R06, R11 | H18: R01 | I18: 実名、稼働枠、独立評価、代行、不足対策がある。 | J18: 全 | K18: 共通 | L18: 共通 | M18: 共通 | N18: G0 | O18: B0-08 | P18: S006,S016,S088 | Q18: AIで調査・仮説・質問を草案化。人が一次情報・実行動・投資判断を確認。 | R18: P1-03,P1-15 | S18: 添付提案の具体化／旧版再編 | T18: U01
A19: B0-16 | B19: 企画 | C19: 計画 | D19: 規模・適用・段階投資の設定 | E19: 工程の深さを機能・危害で決め、各実験への投資上限を設定する。工数レンジは添付案の未較正値として参考表示し自動見積に使わない。 | F19: 適用判定・段階予算 | G19: R03, R15 | H19: R01 | I19: 除外理由、代替証拠、再判定条件を承認。 | J19: 全 | K19: 共通 | L19: 共通 | M19: 共通 | N19: G0 | O19: B0-11,B0-15 | P19: S016,S018,S081 | Q19: AIで調査・仮説・質問を草案化。人が一次情報・実行動・投資判断を確認。 | R19: P1-08,P1-14 | S19: 添付提案の具体化／旧版再編 | T19: U01
A20: B0-17 | B20: 企画 | C20: 実験判断 | D20: 探索証拠と反証の整理 | E20: 需要・技術・採算・安全の未解決を比較し、追加検証の価値を判断する。うまくいかなかった実験結果も削除しない。 | F20: 探索レビュー | G20: R02, R08, R15 | H20: R01 | I20: 最重要仮説に対する証拠と残存不確実性がある。 25の検証状態・必要行動証拠を確認し、未検証の持越しには理由・次実験・上限・再判断日・停止条件を記録。 | J20: 全 | K20: 共通 | L20: 共通 | M20: 共通 | N20: G0 | O20: B0-11,B0-16 | P20: S009,S062,S087,S005 | Q20: AIで調査・仮説・質問を草案化。人が一次情報・実行動・投資判断を確認。 | R20: P2-17,P2-19 | S20: 添付提案の具体化／旧版再編 | T20: U01
A21: B0-18 | B21: 企画 | C21: G0 | D21: 事業探索・予算枠承認 | E21: G0で次の探索・要件の範囲、予算、成功・停止条件を承認する。承認は未解決リスクの免責や全額投資の一括許可としない。 | F21: G0判断記録 | G21: R02, R03 | H21: R01 | I21: Go/条件付き/再検証/停止、条件期限、責任者を記録。 25の検証状態・必要行動証拠を確認し、未検証の持越しには理由・次実験・上限・再判断日・停止条件を記録。 | J21: 全 | K21: 共通 | L21: 共通 | M21: 共通 | N21: G0 | O21: B0-17,B0-10,B0-15 | P21: S001,S081,S104 | Q21: AIで調査・仮説・質問を草案化。人が一次情報・実行動・投資判断を確認。 | R21: P0-06,P2-19,P1-18 | S21: 添付提案の具体化／旧版再編 | T21: U01
A22: B1-01 | B22: 要件 | C22: 価値要件 | D22: Product Goal・KPIツリー | E22: 価値仮説から業務成果、利用行動、品質・安全ガードレールを定義し、分母、観測期間、Ownerを定める。 | F22: Product Goal・KPI定義 | G22: R02, R15 | H22: R01 | I22: 主要指標と悪化させてはいけない指標を承認。 | J22: 全 | K22: 共通 | L22: 共通 | M22: 共通 | N22: G1 | O22: B0-18 | P22: S009,S090 | Q22: 仕様・異常系・評価を草案化。人が業務正解・禁止事項・閾値・利用許可を承認。 | R22: P1-16 | S22: 添付提案の具体化／旧版再編 | T22: U01
A23: B1-02 | B23: 要件 | C23: 業務要件 | D23: As-Is/To-BeとHuman-AI分担 | E23: 通常、例外、承認待ち、誤回答、失敗時を含めて業務を設計する。人間の確認負荷・権限と責任も見積もる。 | F23: 業務フロー・介入設計 | G23: R04, R05, R02 | H23: R02 | I23: 利用者、AI、人の責任と戻り経路が明確。 | J23: 全 | K23: 共通 | L23: 共通 | M23: 共通 | N23: G1 | O23: B1-01 | P23: S019,S032,S095 | Q23: 仕様・異常系・評価を草案化。人が業務正解・禁止事項・閾値・利用許可を承認。 | R23: P1-09 | S23: 添付提案の具体化／旧版再編 | T23: U01
A24: B1-03 | B24: 要件 | C24: スコープ | D24: User Story・受入条件・禁止事項 | E24: Issueごとに利用者、価値、操作範囲、禁止操作、受入観点、評価IDを付ける。要望を機能量で優先順位付けしない。 | F24: Product Spec・Issue | G24: R02, R04, R11 | H24: R02 | I24: 追跡可能な要件IDと評価ID、非対象がある。 | J24: 全 | K24: 共通 | L24: 共通 | M24: 共通 | N24: G1 | O24: B1-02 | P24: S020,S076,S087 | Q24: 仕様・異常系・評価を草案化。人が業務正解・禁止事項・閾値・利用許可を承認。 | R24: P1-10,P1-16 | S24: 添付提案の具体化／旧版再編 | T24: U01
A25: B1-04 | B25: 要件 | C25: データ利用 | D25: データ取得・目的・法令適用判定 | E25: 目的、取得根拠、仮名/匿名区分、委託/第三者提供、外国提供を別々に確認する。実データ受領・調査記録外部送信の前に条件を確定する。 | F25: Privacy Gate・Data許可 | G25: R10, R14, R13 | H25: R14 | I25: 対象Asset、送信先、用途、保持・削除条件を承認。 | J25: 全 | K25: 共通 | L25: 共通 | M25: 共通 | N25: G1 | O25: B0-07,B0-08 | P25: S003,S015,S094 | Q25: 仕様・異常系・評価を草案化。人が業務正解・禁止事項・閾値・利用許可を承認。 | R25: P1-19,P2-03 | S25: 添付提案の具体化／旧版再編 | T25: U01,W02,W03 | U25: https://www.ppc.go.jp/personalinfo/legal/guidelines_anonymous/ https://www.ppc.go.jp/personalinfo/legal/guidelines_offshore/
A26: B1-05 | B26: 要件 | C26: データ要件 | D26: 品質・鮮度・権限・ラベル要件 | E26: 必要範囲、欠損許容、アクセス制御、更新頻度、ラベル基準、評価との分離をデータ要件にする。 | F26: Data Requirement | G26: R09, R10, R11 | H26: R10 | I26: Owner、出所、権利、品質基準、派生資産が定義済。 | J26: 全 | K26: 共通 | L26: 共通 | M26: 共通 | N26: G1 | O26: B1-04 | P26: S031,S055,S056,S058 | Q26: 仕様・異常系・評価を草案化。人が業務正解・禁止事項・閾値・利用許可を承認。 | R26: P1-12,P2-04 | S26: 添付提案の具体化／旧版再編 | T26: U01
A27: B1-06 | B27: 要件 | C27: AI要件 | D27: AI機能境界・自律性・不確実性 | E27: AIに任せる判断、ツール、実行時間、許容失敗、人間承認と非AIフォールバックを定義する。モデルの確信表現を確率と同一視しない。 | F27: AI動作要件 | G27: R08, R04, R11 | H27: R02 | I27: 機能別に期待・禁止・失敗時挙動を記録。 | J27: 全 | K27: 共通 | L27: 共通 | M27: 共通 | N27: G1 | O27: B1-03 | P27: S054,S065,S069 | Q27: 仕様・異常系・評価を草案化。人が業務正解・禁止事項・閾値・利用許可を承認。 | R27: P1-11 | S27: 添付提案の具体化／旧版再編 | T27: U01,W04 | U27: https://www.anthropic.com/engineering/building-effective-agents
A28: B1-07 | B28: 要件 | C28: 評価要件 | D28: 評価母集団・指標・閾値・失敗定義 | E28: 現実の利用分布、重要slice、反復、判定者、標本の限界を決める。万能な精度閾値を置かず重大失敗を別条件にする。 | F28: Eval Plan | G28: R11, R04, R08 | H28: R19 | I28: 指標ごとの分母・閾値・重大条件・根拠がある。 | J28: 全 | K28: 共通 | L28: 共通 | M28: 共通 | N28: G1 | O28: B1-03,B1-05,B1-06 | P28: S052,S067,S070,S077 | Q28: 仕様・異常系・評価を草案化。人が業務正解・禁止事項・閾値・利用許可を承認。 | R28: P1-11,P2-05 | S28: 添付提案の具体化／旧版再編 | T28: U01,W05,W10 | U28: https://www.anthropic.com/engineering/demystifying-evals-for-ai-agents https://www.nist.gov/publications/artificial-intelligence-risk-management-framework-generative-artificial-intelligence
A29: B1-08 | B29: 要件 | C29: 非機能 | D29: SLO・容量・可用性・費用要件 | E29: 利用量、ピーク、遅延、可用性、復旧目標、コスト上限をサービス特性から決める。予算超過時は安全に縮退・停止する。 | F29: NFR・SLO初版 | G29: R12, R08, R15 | H29: R18 | I29: 測定点、時間窓、費用境界、復旧目標を合意。 | J29: 全 | K29: 共通 | L29: 共通 | M29: 共通 | N29: G1 | O29: B1-01,B1-06 | P29: S023,S029,S050 | Q29: 仕様・異常系・評価を草案化。人が業務正解・禁止事項・閾値・利用許可を承認。 | R29: P1-13 | S29: 添付提案の具体化／旧版再編 | T29: U01
A30: B1-09 | B30: 要件 | C30: UX要件 | D30: 透明性・アクセシビリティ・救済 | E30: AI利用表示、根拠・限界、取消・訂正、問い合わせ、必要な人への移管を決める。アクセシビリティと誤信頼を検証対象にする。 | F30: Human-AI UX要件 | G30: R05, R17, R14 | H30: R02 | I30: 重要操作の確認・失敗時案内・救済導線がある。 | J30: 全 | K30: 共通 | L30: 共通 | M30: 共通 | N30: G1 | O30: B1-02 | P30: S032,S095,S096 | Q30: 仕様・異常系・評価を草案化。人が業務正解・禁止事項・閾値・利用許可を承認。 | R30: P2-14,P3-05 | S30: 添付提案の具体化／旧版再編 | T30: U01
A31: B1-10 | B31: 要件 | C31: リスク要件 | D31: Risk Tier確定・独立性の設計 | E31: 用途と影響によりT0〜T3を人が確定する。独立評価者、品質停止権、禁止用途、例外を定め、法的分類は別台帳に置く。 | F31: Risk Tier・評価独立性 | G31: R11, R13, R14 | H31: R01 | I31: 実装・評価・公開承認の利益相反が解消。 | J31: 全 | K31: 共通 | L31: 共通 | M31: 共通 | N31: G1 | O31: B1-04,B1-06,B1-07 | P31: S017,S071,S077,S081 | Q31: 仕様・異常系・評価を草案化。人が業務正解・禁止事項・閾値・利用許可を承認。 | R31: P1-07,P2-16 | S31: 添付提案の具体化／旧版再編 | T31: U01,W01,W10 | U31: https://www.meti.go.jp/shingikai/mono_info_service/ai_shakai_jisso/ https://www.nist.gov/publications/artificial-intelligence-risk-management-framework-generative-artificial-intelligence
A32: B1-11 | B32: 要件 | C32: GTM要件 | D32: オンボーディング・提供条件 | E32: 利用開始、権限設定、初回価値到達、教育、サポート、契約・表示条件を定義する。企業向けの管理者・購買要件も扱う。 | F32: 提供・導入要件 | G32: R16, R17, R05 | H32: R02 | I32: 利用開始と継続の障壁、責任範囲が定義済。 | J32: 全 | K32: 共通 | L32: 共通 | M32: 共通 | N32: G1 | O32: B0-14,B1-09 | P32: S022,S085,S089 | Q32: 仕様・異常系・評価を草案化。人が業務正解・禁止事項・閾値・利用許可を承認。 | R32: P3-23 | S32: 添付提案の具体化／旧版再編 | T32: U01
A33: B1-12 | B33: 要件 | C33: 収益要件 | D33: 価格・課金・利用制限の設計 | E33: 課金メーター、無料枠、上限、返金、過大請求防止を定義する。商用提供しない場合は内部配賦と予算制御で代替する。 | F33: 価格・課金仕様 | G33: R02, R15, R16 | H33: R01 | I33: 課金イベントと原価、説明、返金・取消条件を承認。 | J33: 条件:外販・課金 | K33: 条件 | L33: 条件 | M33: 条件 | N33: G1 | O33: B0-09,B0-10 | P33: S083,S091,S093 | Q33: 仕様・異常系・評価を草案化。人が業務正解・禁止事項・閾値・利用許可を承認。 | S33: 添付提案の具体化／旧版再編 | T33: U01
A34: B1-13 | B34: 要件 | C34: 調達要件 | D34: モデル・クラウド・委託先の条件 | E34: 外部サービスのデータ利用、保存、地域、再委託、EOL、監査、障害通知、SLA、退出条件を調達要件にする。 | F34: 調達・依存条件 | G34: R20, R14, R08 | H34: R20 | I34: 許容できない条件と代替案を記録。 | J34: 条件:外部依存 | K34: 条件 | L34: 条件 | M34: 条件 | N34: G1 | O34: B1-04,B1-08 | P34: S014,S015,S094,S092 | Q34: 仕様・異常系・評価を草案化。人が業務正解・禁止事項・閾値・利用許可を承認。 | R34: P0-05,P2-20 | S34: 添付提案の具体化／旧版再編 | T34: U01
A35: B1-14 | B35: 要件 | C35: AI開発統制 | D35: 開発Agent利用・送信・権限の承認 | E35: 投入可能情報、コード・ログ送信、MCP、実行コマンド、ネットワーク、秘密情報、承認境界を定義する。 | F35: 開発AI利用ポリシー | G35: R06, R13, R14 | H35: R06 | I35: 承認済みツールと送信先、停止・監査の担当が明確。 | J35: 条件:開発AI | K35: 条件 | L35: 条件 | M35: 条件 | N35: G1 | O35: B1-04,B1-10 | P35: S028,S078,S099 | Q35: 仕様・異常系・評価を草案化。人が業務正解・禁止事項・閾値・利用許可を承認。 | R35: P1-23 | S35: 添付提案の具体化／旧版再編 | T35: U01,W06,W12 | U35: https://openai.com/index/harness-engineering/ https://genai.owasp.org/resource/a-practical-guide-for-secure-mcp-server-development/
A36: B1-15 | B36: 要件 | C36: 実験運営 | D36: Evidence Plan・学習ループ設計 | E36: PoCを別契約フェーズにせず、各仮説の最小実験・予算・打切りをIssueにする。必要データと独立評価を先行準備する。 | F36: 実験計画・判定条件 | G36: R02, R08, R11 | H36: R02 | I36: 仮説から実験・評価・判断までID連結済。 | J36: 全 | K36: 共通 | L36: 共通 | M36: 共通 | N36: G1 | O36: B1-07,B1-10 | P36: S062,S087,S104 | Q36: 仕様・異常系・評価を草案化。人が業務正解・禁止事項・閾値・利用許可を承認。 | R36: P1-20,P1-22,P2-01 | S36: 添付提案の具体化／旧版再編 | T36: U01
A37: B1-16 | B37: 要件 | C37: 計画 | D37: ロードマップ・依存・スキル充足 | E37: 価値とリスク低減で優先順位を決め、薄い縦切り実装単位に分割する。工数と経過時間を分け、レビュー容量を制約に含める。 | F37: ロードマップ・要員計画 | G37: R03, R02, R06 | H37: R01 | I37: 担当、依存、予算枠、能力不足、意思決定日がある。 | J37: 全 | K37: 共通 | L37: 共通 | M37: 共通 | N37: G1 | O37: B1-15,B0-15 | P37: S016,S088,S106 | Q37: 仕様・異常系・評価を草案化。人が業務正解・禁止事項・閾値・利用許可を承認。 | R37: P3-02 | S37: 添付提案の具体化／旧版再編 | T37: U01
A38: B1-17 | B38: 要件 | C38: 継続改善 | D38: 変更・廃止・データ権利の要件 | E38: 用途拡大、Provider変更、データ更新、書込み追加を再審査トリガーにする。終了時の移管、保持・削除、通知も要件化する。 | F38: 変更・退出要件 | G38: R18, R10, R14 | H38: R18 | I38: 重大変更と廃止の責任者、条件、再ゲートがある。 | J38: 全 | K38: 共通 | L38: 共通 | M38: 共通 | N38: G1 | O38: B1-10,B1-13 | P38: S080,S081,S103 | Q38: 仕様・異常系・評価を草案化。人が業務正解・禁止事項・閾値・利用許可を承認。 | R38: P4-15,P4-22 | S38: 添付提案の具体化／旧版再編 | T38: U01
A39: B1-18 | B39: 要件 | C39: 計測 | D39: 事業・開発・AIコスト計測の仕様 | E39: 利用者価値と品質、AI人時間、レビュー・手戻り、elapsed time、費用の観測方法を定義する。個人監視を目的にしない。 | F39: 計測計画・同等比較ルール | G39: R15, R03, R11 | H39: R02 | I39: 比較範囲、分母、期間、取得権利、欠測扱いを合意。 | J39: 全 | K39: 共通 | L39: 共通 | M39: 共通 | N39: G1 | O39: B1-01,B1-14 | P39: S079,S090,S093 | Q39: 仕様・異常系・評価を草案化。人が業務正解・禁止事項・閾値・利用許可を承認。 | R39: P1-17,P4-19 | S39: 添付提案の具体化／旧版再編 | T39: U01,W07,W08 | U39: https://metr.org/blog/2026-02-24-uplift-update/ https://dora.dev/ai/roi/calculator/
A40: B1-19 | B40: 要件 | C40: G1 | D40: スコープ・Evidence Plan承認 | E40: 価値、要件、禁止事項、データ利用、評価、予算、体制を承認する。未確定項目は責任者・期限・公開制限を付ける。 | F40: G1判断記録 | G40: R02, R03 | H40: R01 | I40: 受入条件と投資条件が承認され、必要な法令判定済。 | J40: 全 | K40: 共通 | L40: 共通 | M40: 共通 | N40: G1 | O40: B1-07,B1-10,B1-16,B1-17 | P40: S001,S081 | Q40: 仕様・異常系・評価を草案化。人が業務正解・禁止事項・閾値・利用許可を承認。 | R40: P1-21,P2-18 | S40: 添付提案の具体化／旧版再編 | T40: U01
...

Sheet 03_AIリスクTier・適用判定
A1: AIリスクTier・機能・適用判定
A2: T0〜T3は添付案の社内管理区分。製品AIと開発Agentを別々に判断し、法令上の分類は12で管理。
A3: Tier | B3: 名称 | C3: 典型的な影響・用途 | D3: 評価・承認強度 | E3: 注意 | F3: 根拠
A4: T0 | B4: 最小 | C4: 公開情報中心・限定された社内補助・重要判断/書込みなし | D4: 実装者以外のpeer review＋回帰 | E4: 公開情報でも危害・権限によって上位へ | F4: U01
A5: T1 | B5: 通常 | C5: 顧客FAQ/RAG等。重要な判断や自律書込みなし | D5: 実装から分離したEvaluator＋Frozen Set | E5: 社内/小規模だからT0とはしない | F5: U01
A6: T2 | B6: 高 | C6: 個人情報・取引・外部書込み・金銭/契約等の影響 | D6: 独立QA/Safety、Security、Red Team、停止権 | E6: 個人情報の有無だけで法的分類と同一視しない | F6: U01
A7: T3 | B7: 重大 | C7: 生命・身体・権利の重大影響・規制業務・高度自律 | D7: 組織的独立性＋必要に応じ外部専門評価＋経営受容 | E7: 禁止用途はTierにかかわらず実施しない | F7: U01
A11: 案件判定（両境界を記入）
A12: 判定軸 | B12: 確認事項 | C12: 製品AI（入力） | D12: 開発Agent（入力） | E12: 根拠・承認URI（入力） | F12: 確認状態
A13: 対象と境界 | B13: 製品AI / 開発Agent / 評価AI / 運用Agentを区別 | F13: 未判定
A14: 危害と対象者 | B14: 生命・権利・金銭・未成年・脆弱な利用者 | F14: 未判定
A15: データ | B15: 個人情報、機密、仮名/匿名、権利、外部送信 | F15: 未判定
A16: 自律度・副作用 | B16: read-only、承認付き書込み、自律書込み、取り消し可能性 | F16: 未判定
A17: Tool/MCP・委譲 | B17: 認可範囲、chain、ID、ネットワーク、秘密 | F17: 未判定
A18: 取得・配置 | B18: 外部API、ローカルモデル、クラウド、閉域 | F18: 未判定
A19: RAG・学習 | B19: RAG、GraphRAG、追加学習、自前学習、不要な複雑性 | F19: 未判定
A20: 地域・法的役割 | B20: 提供国、利用者、処理国、AI Act等のactor role | F20: 未判定
A21: 残存リスク | B21: 重大未対策、利用禁止、例外期限、停止方法 | F21: 未判定
A22: 確定Tier・承認 | B22: 根拠、A実名、日付、見直しトリガー | F22: 未判定
A24: 機能判定：方式・配置・学習を独立に判定する（AR02/04）
A26: 機能／境界 | B26: 採用判定 | C26: 具体的な実施形態 | D26: 必須評価・能力 | E26: 判断者 | F26: 承認URI
A27: RAG | B27: 未判定 | C27: 検索拡張。API／ローカルを問わない | D27: B4-03、E03/E04、S061
A28: Agent | B28: 未判定 | C28: 外部ツール操作。read-onlyも成否を評価 | D28: B4-04、E05、S065
A29: 子Agent | B29: 未判定 | C29: 親子委譲・共有状態がある場合 | D29: 14の親子試験。単独Agentには強制しない
A30: 追加学習 | B30: 未判定 | C30: 微調整／独自学習を行う場合 | D30: データ来歴・学習／評価分離・重み処理
A31: 外部API | B31: 未判定 | C31: API型のモデル／評価／ログ送信 | D31: 認証・送信・レート・費用・切替
A32: 自己ホスト | B32: 未判定 | C32: モデルを自社管理の実行基盤で提供 | D32: 配備・容量・モデル権利・復元
A35: 外部APIのみ | B35: RAG/Agentを自動適用しない | C35: S034/S035・送信判定。機能は別途判定
A36: ローカルRAG | B36: RAG=使用、自己ホスト=使用 | C36: S061、B4-03、E03/E04は必要
A37: 追加学習 | B37: 追加学習=使用 | C37: S066等。RAGとは別の軸
A38: 書込みAgent | B38: Agent=使用、書込みを03で高影響判定 | C38: S065、B4-04/E05。小規模でも権限・復旧を省略しない

Sheet 04_規模・テーラリング
A1: 規模とテーラリング｜人数・工数は案件で較正
A2: 原稿の参考値を保存しつつ、実行予算・人数には自動転記しない。AI効果は実測後に反映する。
A3: 区分 | B3: 観点 | C3: 適用の考え方 | D3: 具体的な運用 | E3: 留保・禁止する短絡 | F3: 根拠
A4: S | B4: 参考構成 | C4: 機能1〜2、統合2〜4、外部基盤モデル中心 | D4: 文書を統合・兼務可。必要な評価独立性は残す | E4: 添付のコア4〜6FTEとロール別合計は一致しないため自動人数採用しない | F4: U01
A5: M | B5: 参考構成 | C5: 複数機能、統合5〜10、RAG/限定Agent | D5: 依存と共有基盤、QA/支援容量を明示 | E5: 個人情報や書込みは人数でなく危害により審査 | F5: U01
A6: L | B6: 参考構成 | C6: 多事業・多地域・高影響・多数統合 | D6: ポートフォリオ、チーム間依存、独立評価の仕組み | E6: 大規模事前学習の研究/GPU費は別計画 | F6: U01
A7: 全 | B7: 省略不可の原則 | C7: 責任・利用許可・安全境界・受入評価・公開判断 | D7: 不要な機能は除外可、必要な統制は代替証拠で維持 | E7: 法令や重大な品質停止条件を例外承認で無効化しない | F7: U01
A8: 全 | B8: 工程テーラリング | C8: 適用 / 対象外 / 未判定を17で記録 | D8: 理由、代替、A、日付、変更トリガーが必要 | E8: 物理構成数の合理化と安全な境界の省略は別。本番秘密・データ・権限を開発Agentから分離し、必要な独立検証・復旧試験を確保。 | F8: U01
A9: 全 | B9: 管理単位 | C9: 標準タスクは工程の枠、実行単位はIssue/Run | D9: 反復は新しいIssue・評価Run・Release版を残す | E9: 同じ評価記録を上書きして成功扱いしない | F9: U01,U03
A13: 添付原稿の参考工数（未較正・AI削減控除なし）
A14: 工程 | B14: S下限 | C14: S上限 | D14: M下限 | E14: M上限 | F14: L下限 | G14: L上限 | H14: 単位・範囲
A15: 企画 | B15: 10 | C15: 20 | D15: 25 | E15: 50 | F15: 50 | G15: 100 | H15: 人日／初期計画レンジ
A16: 要件 | B16: 15 | C16: 30 | D16: 35 | E16: 75 | F16: 80 | G16: 160 | H16: 同上
A17: 設計 | B17: 20 | C17: 45 | D17: 50 | E17: 110 | F17: 120 | G17: 250 | H17: 同上
A18: 実装 | B18: 45 | C18: 110 | D18: 140 | E18: 350 | F18: 350 | G18: 900 | H18: 同上
A19: 評価 | B19: 25 | C19: 60 | D19: 80 | E19: 180 | F19: 200 | G19: 500 | H19: 同上
A20: 運用立上げ | B20: 20 | C20: 45 | D20: 60 | E20: 140 | F20: 150 | G20: 350 | H20: 継続運用は含めない
A21: 廃止 | B21: 5 | C21: 15 | D21: 15 | E21: 40 | F21: 40 | G21: 100 | H21: 将来の一時作業。初期Buildと同一時期ではない
A22: 継続運用/月 | B22: 5 | C22: 12 | D22: 15 | E22: 40 | F22: 40 | G22: 100 | H22: L上限は原稿100+。100は上限保証ではない

Sheet 05_意思決定・RACI
A1: 意思決定・RACI｜承認Aを一意にする
A2: R=実施責任、A=最終承認、C=必須相談、I=共有。実名と代行は06、承認の実記録は29へ。
A3: 判断ID | B3: 判断対象 | C3: R | D3: A（原則1） | E3: C | F3: I | G3: 判断時点 | H3: 必要な証拠・独立性
A4: D01 | B4: 探索・事業開始/投資 | C4: R02,R03 | D4: R01 | E4: R15,R06,R14 | F4: R18,R16 | G4: G0/G1/G2 | H4: 仮説・予算・停止条件
A5: D02 | B5: AI利用・Tier | C5: R02,R08 | D5: R01 | E5: R13,R14,R11 | F5: R18,R20 | G5: G0/G1・重大変更 | H5: 用途・危害・残存リスク
A6: D03 | B6: 個人データ・外国送信 | C6: R10 | D6: R14 | E6: R13,R02 | F6: R09,R08,R20 | G6: 取得・送信より前 | H6: Data Flow・根拠・目的・条件
A7: D04 | B7: Architecture/Harness | C7: R06 | D7: R06 | E7: R08,R09,R12,R13,R11 | F7: R03,R18 | G7: G2技術勧告 | H7: 独立レビュー証跡を添付
A8: D05 | B8: 評価合否 | C8: R11 | D8: R19 | E8: R04,R13,R14 | F8: R02,R18 | G8: G3・重大変更 | H8: Frozen Eval・grader・限界
A9: D06 | B9: 本番公開・停止/復旧 | C9: R12 | D9: R18 | E9: R19,R13,R14,R02 | F9: R01,R17,R16 | G9: G3・変更公開 | H9: 品質合否・Runbook・対象版
A10: D07 | B10: 重大リスクの受容 | C10: R18 | D10: R01 | E10: R19,R13,R14 | F10: R02,R03 | G10: G3等 | H10: 不合格の上書きではない
A11: D08 | B11: 外部成果物受入 | C11: R20 | D11: R20 | E11: R06,R11,R14 | F11: R03,R18 | G11: 契約別 | H11: ここにだけ契約検収を置く
A12: D09 | B12: Scale/Continue/Pivot/Stop | C12: R02,R15 | D12: R01 | E12: R18,R19,R16 | F12: R03,R17 | G12: G4 | H12: 価値・安全・継続・採算
A13: D10 | B13: 廃止完了 | C13: R18 | D13: R01 | E13: R10,R13,R14,R19 | F13: R17,R20 | G13: G5 | H13: 削除・保全・失効・請求
A14: D11 | B14: Skill公開・権限変更 | C14: R07,R08 | D14: R06 | E14: R13,R11 | F14: R03,R12 | G14: Skill変更時 | H14: 供給網・回帰・実行Policy

Sheet 06_ロール・要員計画
A1: ロール・要員計画｜必要能力と実名・稼働を分離
A2: Roleは専任人数ではない。PersonIDで兼務を束ね、管理基準日時点の合計FTEを点検。期間全体の最大負荷は別途計画。
A3: Role ID | B3: ロール | C3: 主要責任 | D3: 関与・判断 | E3: 兼務・独立性の注意 | F3: 中核Skill | G3: 担当実名（入力） | H3: 所属（入力） | I3: 対象期間（入力） | J3: 必要FTE（入力） | K3: 割当FTE（入力） | L3: 不足FTE | M3: 代行（入力） | N3: 補充/外部活用（入力） | O3: 証拠URI（入力） | P3: PersonID | Q3: 配置開始 | R3: 配置終了 | S3: 当日合計FTE | T3: 当人の当日上限FTE | U3: 稼働点検
A4: R01 | B4: Business Owner / Executive Sponsor | C4: 事業P/L、段階投資、リスク受容、拡大・撤退 | D4: G0/G1/G2/G4/G5。G3は重大リスク受容を支援 | E4: 評価の不合格や法的禁止を事業判断で上書きしない | F4: S008,S009,S010,S081,S104 | L4: =IF(COUNT(J4:K4)<2,"",MAX(0,J4-K4)) | S4: =IF(OR(P4="",COUNT(Q4:R4)<2),"",SUMIFS($K$4:$K$23,$P$4:$P$23,P4,$Q$4:$Q$23,"<="&AsOfDate,$R$4:$R$23,">="&AsOfDate)) | T4: 1 | U4: =IF(P4="","Person未割当",IF(OR(G4="",COUNT(Q4,R4,K4,T4)<4),"配置期間・FTE不足",IF(OR(Q4>R4,K4<0,T4<0),"配置値不正",IF(S4>T4,"当日FTE超過","当日稼働記録あり")))) -> Person未割当
A5: R02 | B5: Product Manager / Product Owner | C5: 顧客課題、価値、Product Goal、優先順位、UX受入 | D5: 企画〜運用の価値と要件の責任 | E5: 納期管理のPMと区別。事業・品質の自己承認を避ける | F5: S004,S009,S020,S082,S087 | L5: =IF(COUNT(J5:K5)<2,"",MAX(0,J5-K5)) | S5: =IF(OR(P5="",COUNT(Q5:R5)<2),"",SUMIFS($K$4:$K$23,$P$4:$P$23,P5,$Q$4:$Q$23,"<="&AsOfDate,$R$4:$R$23,">="&AsOfDate)) | T5: 1 | U5: =IF(P5="","Person未割当",IF(OR(G5="",COUNT(Q5,R5,K5,T5)<4),"配置期間・FTE不足",IF(OR(Q5>R5,K5<0,T5<0),"配置値不正",IF(S5>T5,"当日FTE超過","当日稼働記録あり")))) -> Person未割当
A6: R03 | B6: Delivery PM / Project Manager | C6: 計画、依存、予算枠、進捗、変更、承認証跡 | D6: 全工程の実行調整 | E6: PdM兼務可。ただし事業仮説と実行進捗を混同しない | F6: S006,S016,S079,S106 | L6: =IF(COUNT(J6:K6)<2,"",MAX(0,J6-K6)) | S6: =IF(OR(P6="",COUNT(Q6:R6)<2),"",SUMIFS($K$4:$K$23,$P$4:$P$23,P6,$Q$4:$Q$23,"<="&AsOfDate,$R$4:$R$23,">="&AsOfDate)) | T6: 1 | U6: =IF(P6="","Person未割当",IF(OR(G6="",COUNT(Q6,R6,K6,T6)<4),"配置期間・FTE不足",IF(OR(Q6>R6,K6<0,T6<0),"配置値不正",IF(S6>T6,"当日FTE超過","当日稼働記録あり")))) -> Person未割当
A7: R04 | B7: Domain SME | C7: 業務正解、例外、誤りの被害、ラベル判断 | D7: 要件・評価・顧客業務 | E7: 実装者の期待に合わせて正解を変更しない | F7: S007,S019,S058,S071 | L7: =IF(COUNT(J7:K7)<2,"",MAX(0,J7-K7)) | S7: =IF(OR(P7="",COUNT(Q7:R7)<2),"",SUMIFS($K$4:$K$23,$P$4:$P$23,P7,$Q$4:$Q$23,"<="&AsOfDate,$R$4:$R$23,">="&AsOfDate)) | T7: 1 | U7: =IF(P7="","Person未割当",IF(OR(G7="",COUNT(Q7,R7,K7,T7)<4),"配置期間・FTE不足",IF(OR(Q7>R7,K7<0,T7<0),"配置値不正",IF(S7>T7,"当日FTE超過","当日稼働記録あり")))) -> Person未割当
A8: R05 | B8: UX Research / Product Designer | C8: 調査、Human-AI UX、利用者理解、アクセシビリティ | D8: 探索〜利用定着 | E8: ユーザー研究と営業の希望的解釈を分離 | F8: S021,S032,S082,S095,S096 | L8: =IF(COUNT(J8:K8)<2,"",MAX(0,J8-K8)) | S8: =IF(OR(P8="",COUNT(Q8:R8)<2),"",SUMIFS($K$4:$K$23,$P$4:$P$23,P8,$Q$4:$Q$23,"<="&AsOfDate,$R$4:$R$23,">="&AsOfDate)) | T8: 1 | U8: =IF(P8="","Person未割当",IF(OR(G8="",COUNT(Q8,R8,K8,T8)<4),"配置期間・FTE不足",IF(OR(Q8>R8,K8<0,T8<0),"配置値不正",IF(S8>T8,"当日FTE超過","当日稼働記録あり")))) -> Person未割当
A9: R06 | B9: Engineering Owner / Tech Lead | C9: 技術設計、実装品質、Harness、技術投資 | D9: G2技術勧告、実装と保守 | E9: 独立品質の最終判定はR19。少人数時は外部レビューを手配 | F9: S030,S034,S076,S097,S100 | L9: =IF(COUNT(J9:K9)<2,"",MAX(0,J9-K9)) | S9: =IF(OR(P9="",COUNT(Q9:R9)<2),"",SUMIFS($K$4:$K$23,$P$4:$P$23,P9,$Q$4:$Q$23,"<="&AsOfDate,$R$4:$R$23,">="&AsOfDate)) | T9: 1 | U9: =IF(P9="","Person未割当",IF(OR(G9="",COUNT(Q9,R9,K9,T9)<4),"配置期間・FTE不足",IF(OR(Q9>R9,K9<0,T9<0),"配置値不正",IF(S9>T9,"当日FTE超過","当日稼働記録あり")))) -> Person未割当
A10: R07 | B10: Application Engineer | C10: API、UI、業務ロジック、テスト、Tool実装 | D10: 設計・実装・保守 | E10: AI生成物にも通常と同じ実装責任を負う | F10: S024,S037,S039,S040,S042 | L10: =IF(COUNT(J10:K10)<2,"",MAX(0,J10-K10)) | S10: =IF(OR(P10="",COUNT(Q10:R10)<2),"",SUMIFS($K$4:$K$23,$P$4:$P$23,P10,$Q$4:$Q$23,"<="&AsOfDate,$R$4:$R$23,">="&AsOfDate)) | T10: 1 | U10: =IF(P10="","Person未割当",IF(OR(G10="",COUNT(Q10,R10,K10,T10)<4),"配置期間・FTE不足",IF(OR(Q10>R10,K10<0,T10<0),"配置値不正",IF(S10>T10,"当日FTE超過","当日稼働記録あり")))) -> Person未割当
A11: R08 | B11: AI / ML Engineer | C11: モデル選定、RAG、Agent、学習、AI評価・改善 | D11: 要件〜運用 | E11: 凍結評価セットをモデル調整に流用しない | F11: S054,S061,S064,S065,S068 | L11: =IF(COUNT(J11:K11)<2,"",MAX(0,J11-K11)) | S11: =IF(OR(P11="",COUNT(Q11:R11)<2),"",SUMIFS($K$4:$K$23,$P$4:$P$23,P11,$Q$4:$Q$23,"<="&AsOfDate,$R$4:$R$23,">="&AsOfDate)) | T11: 1 | U11: =IF(P11="","Person未割当",IF(OR(G11="",COUNT(Q11,R11,K11,T11)<4),"配置期間・FTE不足",IF(OR(Q11>R11,K11<0,T11<0),"配置値不正",IF(S11>T11,"当日FTE超過","当日稼働記録あり")))) -> Person未割当
A12: R09 | B12: Data Engineer / Steward | C12: 取得、品質、パイプライン、権限・削除伝播 | D12: 全データライフサイクル | E12: Data Ownerの利用許可を技術者判断で代替しない | F12: S025,S031,S055,S056,S080 | L12: =IF(COUNT(J12:K12)<2,"",MAX(0,J12-K12)) | S12: =IF(OR(P12="",COUNT(Q12:R12)<2),"",SUMIFS($K$4:$K$23,$P$4:$P$23,P12,$Q$4:$Q$23,"<="&AsOfDate,$R$4:$R$23,">="&AsOfDate)) | T12: 1 | U12: =IF(P12="","Person未割当",IF(OR(G12="",COUNT(Q12,R12,K12,T12)<4),"配置期間・FTE不足",IF(OR(Q12>R12,K12<0,T12<0),"配置値不正",IF(S12>T12,"当日FTE超過","当日稼働記録あり")))) -> Person未割当
A13: R10 | B13: Data Owner | C13: データ利用目的、権利、品質、保存削除責任 | D13: 取得前から廃止後保全まで | E13: 法的判断はR14。個人データ処理の根拠を残す | F13: S003,S055,S056,S103 | L13: =IF(COUNT(J13:K13)<2,"",MAX(0,J13-K13)) | S13: =IF(OR(P13="",COUNT(Q13:R13)<2),"",SUMIFS($K$4:$K$23,$P$4:$P$23,P13,$Q$4:$Q$23,"<="&AsOfDate,$R$4:$R$23,">="&AsOfDate)) | T13: 1 | U13: =IF(P13="","Person未割当",IF(OR(G13="",COUNT(Q13,R13,K13,T13)<4),"配置期間・FTE不足",IF(OR(Q13>R13,K13<0,T13<0),"配置値不正",IF(S13>T13,"当日FTE超過","当日稼働記録あり")))) -> Person未割当
A14: R11 | B14: QA / AI Evaluation Engineer | C14: 評価計画、独立セット、統計、回帰、敵対的評価 | D14: 要件から継続評価 | E14: 実装とは別に評価データを管理し、品質停止を勧告 | F14: S052,S059,S067,S070,S077 | L14: =IF(COUNT(J14:K14)<2,"",MAX(0,J14-K14)) | S14: =IF(OR(P14="",COUNT(Q14:R14)<2),"",SUMIFS($K$4:$K$23,$P$4:$P$23,P14,$Q$4:$Q$23,"<="&AsOfDate,$R$4:$R$23,">="&AsOfDate)) | T14: 1 | U14: =IF(P14="","Person未割当",IF(OR(G14="",COUNT(Q14,R14,K14,T14)<4),"配置期間・FTE不足",IF(OR(Q14>R14,K14<0,T14<0),"配置値不正",IF(S14>T14,"当日FTE超過","当日稼働記録あり")))) -> Person未割当
A15: R12 | B15: SRE / Platform Engineer | C15: 基盤、監視、SLO、配備、復旧、費用計測 | D15: 設計〜廃止 | E15: 運用Agentも最小権限。重大な実行は承認対象 | F15: S023,S033,S045,S048,S049 | L15: =IF(COUNT(J15:K15)<2,"",MAX(0,J15-K15)) | S15: =IF(OR(P15="",COUNT(Q15:R15)<2),"",SUMIFS($K$4:$K$23,$P$4:$P$23,P15,$Q$4:$Q$23,"<="&AsOfDate,$R$4:$R$23,">="&AsOfDate)) | T15: 1 | U15: =IF(P15="","Person未割当",IF(OR(G15="",COUNT(Q15,R15,K15,T15)<4),"配置期間・FTE不足",IF(OR(Q15>R15,K15<0,T15<0),"配置値不正",IF(S15>T15,"当日FTE超過","当日稼働記録あり")))) -> Person未割当
... A23: R20 | B23: Procurement / Vendor Owner | C23: 調達、DPA・SOW・SLA、外注受入、解約 | D23: 外部依存を横断管理 | E23: 外注受入と自社製品の公開判断は別 | F23: S014,S092,S094 | L23: =IF(COUNT(J23:K23)<2,"",MAX(0,J23-K23)) | S23: =IF(OR(P23="",COUNT(Q23:R23)<2),"",SUMIFS($K$4:$K$23,$P$4:$P$23,P23,$Q$4:$Q$23,"<="&AsOfDate,$R$4:$R$23,">="&AsOfDate)) | T23: 1 | U23: =IF(P23="","Person未割当",IF(OR(G23="",COUNT(Q23,R23,K23,T23)<4),"配置期間・FTE不足",IF(OR(Q23>R23,K23<0,T23<0),"配置値不正",IF(S23>T23,"当日FTE超過","当日稼働記録あり")))) -> Person未割当
A26: 人数・FTEの読み方
A27: 項目 | B27: 説明 | C27: 注意
A28: 専任人数とは別 | B28: 1人が複数ロールを兼務可能。ただし稼働は重複計上しない | C28: 全ロールのFTE足し算を採用人数に変換しない
A29: 元資料のレンジ | B29: 添付にはコアFTEとロール別必要FTEの両方がある | C29: 総量の整合が未確定のため本表は入力から開始
A30: 独立性 | B30: R19の最終品質承認と実装担当は分離 | C30: 不足時は横断組織や外部レビューを明示

Sheet 07_スキル辞書
A1: スキル辞書｜Lv1〜3の行動と証拠
A2: 106スキル。Lv0=当該業務に関与なし、Lv1=指導下、Lv2=自律遂行、Lv3=設計・指導・例外判断。人の習熟度を評価する。
A3: Skill ID | B3: 軸 | C3: 分類 | D3: スキル名 | E3: 定義 | F3: Lv1 | G3: Lv2 | H3: Lv3 | I3: 判定エビデンス | J3: 関連B-ID | K3: 旧v3 Skill | L3: 根拠ID | M3: 再編・適用メモ
A4: S001 | B4: ビジネス | C4: 共通基礎 | D4: 七工程と事業投資・公開ゲートの運用 | E4: 企画〜廃止とG0〜G5で価値・投資・公開・継続判断を運営し、外注品質受入を分離する。 | F4: 各Gateの判断者と必要証拠を説明できる。 | G4: Evidenceと予算枠を確認し、未承認の本番公開や投資を止められる。 | H4: 事業段階とリスクに応じてGateを設計し、重大変更の再審査を主導できる。 | I4: G0〜G5判断記録・再Gate計画 | J4: B0-01,B0-18,B1-19,B2-20,B6-10 | K4: SK01 | L4: U01,U02 | M4: 受託契約中心の定義を事業投資・プロダクト責任へ明示的に変更。
A5: S002 | B5: ビジネス | C5: 法務・ガバナンス | D5: AIガバナンスと関連法規の適用 | E5: 法令と非拘束的な指針を区別し、業種・用途・提供地域・処理地域から適用法を確認する。AI事業者ガイドライン1.2を参照し、根拠版・確認日・再審査条件を管理する。 | F5: AI事業者ガイドラインの共通の指針（人間中心／安全性／公平性／プライバシー保護／セキュリティ確保／透明性／アカウンタビリティ／教育・リテラシー／公正競争確保／イノベーション）を列挙し、指示のもとで担当タスクとの対応表に記入できる。 | G5: 案件のリスク特性から適用枠組み（AI事業者ガイドライン／ISO/IEC 42001／NIST AI RMF／EU AI Actの適用有無）を選定し、リスク管理台帳と責任あるAI評価レポートにガバナンス観点を反映できる。技術障害と区別したAIインシデントの定義を作成できる。 | H5: 対象事業の業種・利用形態に応じたガバナンス方針を設計し、EU AI Actの高リスク該当性や海外案件の枠組み選択の判断根拠を文書化できる。AIインシデント発生時の本人通知・当局報告・対外説明の手順を策定し、判断を主導できる。 | I5: リサーチ資料、リスク管理台帳 v1、責任あるAI評価レポート、モデルカード、AIインシデント対応手順書 | J5: B0-02,B0-08,B5-20,B5-22 | K5: SK02 | L5: U02 | M5: 受託版の行動基準を自社事業向けに再編。関連タスクは本版B-IDで再定義。
A6: S003 | B6: ビジネス | C6: 法務・ガバナンス | D6: 個人情報保護法の適用判定とデータガバナンス | E6: 取得・保有する個人データについて委託か第三者提供かを判定フローで確定し、法的区分と取扱い条件（保管・マスキング・保持期間・越境・外部API送信可否）を決める。 | F6: 個人情報・個人データ・仮名加工情報・匿名加工情報の区別を説明できる。ハッシュ化だけで法定の仮名加工情報/匿名加工情報になるとは判断しない。 | G6: 利用目的・委託/第三者提供・外国提供・外部AI利用を分けて判定し、法務とデータ利用条件を合意できる。仮名加工情報の第三者提供禁止と法定例外を区別し、同意だけで一般に提供可能としない。 | H6: 越境移転・再委託・仮名加工情報の内部利用など非定型の論点を法務と協議して方針化し、データ提供・利用契約の条項に落とせる。「匿名化」の誤用や目的外利用のリスクを他メンバーの成果物からレビューで検出し指導できる。 | I6: 個人情報取扱い判定書、データ提供・利用契約、データ要件定義書、データ受領記録、アクセス制御設定 | J6: B0-07,B1-04,B2-03,B4-07,B5-20,B6-04,B6-11 | K6: SK03 | L6: U02 | M6: 受託版の行動基準を自社事業向けに再編。関連タスクは本版B-IDで再定義。
A7: S004 | B7: ビジネス | C7: 顧客折衝 | D7: ヒアリングと課題定義 | E7: 対象事業の表面的な要望の奥にある業務課題を対話で引き出し、課題・目標・制約・リソースに分類して優先順位を付ける。 | F7: 標準ヒアリングリストの8カテゴリで質問を用意し、同席したヒアリングの記録を作成して課題候補を抽出できる。 | G7: 60〜120分のヒアリングを単独で実施し、解決策の要望（「チャットボットが欲しい」）を業務課題に翻訳して、重要度・緊急度・実現可能性で優先順位を付けた課題リストを完成させられる。 | H7: 経営層を含む複数階層へのヒアリングを設計し、「なぜそれが必要か」まで掘り下げて課題定義書と価値仮説ステートメントに結実させられる。ヒアリング設計を指導し、質問リストの社内標準を改訂できる。 | I7: ヒアリングリスト、ヒアリング記録、課題リスト（優先順位付き）、ヒアリング議事録、課題定義書 | J7: B0-03,B0-04 | K7: SK04 | L7: U02 | M7: 受託版の行動基準を自社事業向けに再編。関連タスクは本版B-IDで再定義。
A8: S005 | B8: ビジネス | C8: 顧客折衝 | D8: ファシリテーション・交渉・合意形成 | E8: ワークショップ・会議体で意見を引き出し時間内に結論へ導く。利害が対立する場面で合意点を作り、決定を議事録として残す。 | F8: アジェンダとタイムラインを準備し、議事録を決定事項・保留事項・宿題に分けて作成できる。 | G8: 業務フローワークショップやキックオフを単独で進行し、発散と収束を制御して合意事項を議事録に確定できる。反対意見が出た場合に論点を整理して次アクションに変換できる。 | H8: ステアリングコミッティやQBRなど経営層を含む会議を設計・進行し、Go/No-Goのような重い判断を根拠付きで合意に導ける。会議設計を指導し、難航する交渉を引き取れる。 | I8: キックオフ議事録、意思決定議事録（判断根拠を明記）、QBR資料、UATフィードバックリストと対応計画 | J8: B0-17 | K8: SK05 | L8: U02 | M8: 受託版の行動基準を自社事業向けに再編。関連タスクは本版B-IDで再定義。
A9: S006 | B9: ビジネス | C9: 顧客折衝 | D9: ステークホルダー分析とRACI運用 | E9: 意思決定者・業務部門・情報システム部門・エンドユーザー・法務を特定し、期待・関心・影響力・懸念をマッピングしてRACIで役割の曖昧さを排除する。 | F9: 組織図からステークホルダーを列挙し、関心度と影響力の2軸マップに配置できる。R/A/C/Iの定義を区別して既存チャートを読める。 | G9: 利用部門側関与者（事業責任者／業務責任者／SME／IT担当／法務／データ管理者）と自社ロール（R1〜R5）を分けてRACIチャート v1を完成させ、利用部門側責任一覧に担当者・期限・数値を落とし込める。 | H9: 少人数体制の兼務マップを設計し、兼務時の分離ルール（本番デプロイ承認は実装者以外、モデル評価は学習実施者以外がレビュー）を定めてRACI v2に反映できる。キーパーソンの抵抗を早期に検知して対処方針を決められる。 | I9: ステークホルダーマップ、RACIチャート v1、RACIチャート v2、利用部門の責任・権限一覧、運用体制図 | J9: B0-01,B0-15,B5-01 | K9: SK06 | L9: U02 | M9: 受託版の行動基準を自社事業向けに再編。関連タスクは本版B-IDで再定義。
A10: S007 | B10: ビジネス | C10: 顧客折衝 | D10: ドメイン知識の獲得と活用 | E10: 対象業界・業務の構造、専門用語、規制、KPIを短期間で把握し、現実的で価値のあるAIソリューションを構想する。 | F10: 業界レポートと顧客公開資料から事業構造・主要業務プロセス・関連規制をA4 1〜2枚に整理できる。業務担当者の用語を用語集にまとめられる。 | G10: 業務担当者と対等に議論できる水準で業務を理解し、As-Is業務フロー図を自力で作成して例外処理まで記述できる。データの業務的意味（外れ値が実在の事象か）をSMEに確認して判断できる。 | H10: 複数案件で蓄積した業界知見から顧客が気づいていない課題や適用領域を提案できる。新規業界への参入時に調査観点を設計し、チームの学習を主導できる。 | I10: リサーチ資料、As-Is業務フロー図、業務適合性評価レポート、ヒアリング議事録 | J10: B0-02 | K10: SK07 | L10: U02 | M10: 受託版の行動基準を自社事業向けに再編。関連タスクは本版B-IDで再定義。
A11: S008 | B11: ビジネス | C11: 事業価値 | D11: 事業戦略理解とビジネス分析フレームワークの活用 | E11: 対象事業の経営戦略・市場環境を3C・SWOT等で構造化し、AIプロジェクトの位置づけと投資判断の文脈を説明する。 | F11: 3C・SWOTの枠組みに顧客情報を当てはめ、指示のもとで分析シートの下書きを作成できる。 | G11: 分析結果から「このAI投資が対象事業のどの戦略目標に貢献するか」を説明し、実現可能性評価レポートの財務・運用観点に接続できる。市場性を評価すべき案件（対外サービス提供型）とそうでない案件を区別できる。 | H11: 複数のAI施策候補を経営戦略への貢献度で比較評価し、優先順位と投資配分を提言できる。QBRで次期の戦略提案を主導できる。 | I11: リサーチ資料、実現可能性評価レポート、QBR資料、次期提案、提案書 | J11: B0-02,B0-05 | K11: SK08 | L11: U02 | M11: 受託版の行動基準を自社事業向けに再編。関連タスクは本版B-IDで再定義。
A12: S009 | B12: ビジネス | C12: 事業価値 | D12: 価値仮説の定義とKPI設計 | E12: 「誰の・どんな課題を・どのように解決し・どのような価値を提供するか」を言語化し、SMART原則に沿った目標とPoCのKPI・アクション基準を設計する。 | F12: 価値仮説のテンプレートに顧客情報を当てはめて下書きし、既存KPIがSMARTの5要素を満たすかをチェックリストで判定できる。 | G12: 定量的な期待効果を含む価値仮説ステートメントとSMART目標を作成し、In-Scope/Out-of-Scopeを具体的に列挙したスコープ定義書を完成させられる。PoC計画書に技術KPIとビジネスKPIを両方定義できる。 | H12: KPI達成度別のネクストアクション（移行／追加PoC／中止）をルール化して事前に関係責任者と合意できる。AI導入自体が目的化した案件を検知し、価値仮説から再定義するよう顧客を導ける。 | I12: 価値仮説ステートメント、課題定義書、SMART目標、スコープ定義書、PoC計画書（実験計画・承認の別紙） | J12: B0-05,B0-17,B1-01,B5-02 | K12: SK09 | L12: U02 | M12: 受託版の行動基準を自社事業向けに再編。関連タスクは本版B-IDで再定義。
A13: S010 | B13: ビジネス | C13: 事業価値 | D13: ROI・TCO試算と感度分析 | E13: 開発・評価・レビュー・手戻り・運用・外部依存を含むTCOと便益を、案件に合う期間で比較する。現金支出削減と余力創出・収益仮説を区別し、対照・前提・感度・不確実性を示す。 | F13: 与えられた前提（人件費単価、現行コスト、想定削減時間）を試算シートに入力し、指示のもとで回収期間を計算できる。 | G13: 便益を3区分に分けて稼働開始月で按分し（初年度は立ち上げ係数）、収益仮説を悲観・標準・楽観の3シナリオで示し、回収期間を定義式（累積純キャッシュフローが0を超える時点）で再計算できるROI試算シートを完成させられる。 | H13: 感度分析の変数選定と前提の妥当性を関係責任者と交渉して合意させ、運用の変動費（トークン消費等）を織り込んだTCOを設計できる。ROI前提と実測値の乖離を分析して次期投資判断に接続できる。 | I13: ROI試算シート（感度分析付き）、実現可能性評価レポート、コストダッシュボード | J13: B0-10,B4-10,B6-09 | K13: SK10 | L13: U02 | M13: 受託版の行動基準を自社事業向けに再編。関連タスクは本版B-IDで再定義。
A14: S011 | B14: ビジネス | C14: 事業価値 | D14: ビジネス価値の可視化と定例レポーティング・QBR運営 | E14: 事業価値・品質・費用・継続利用の実測を仮説と比較し、継続・拡大・ピボット・縮小・停止の判断につなげる。 | F14: 監視ダッシュボードとインシデント記録から、指示された項目を月次レポートのフォーマットに転記して作成できる。 | G14: SLA遵守状況・モデル性能推移・検知したドリフト・実施した改善を月次／四半期レポートにまとめ、技術指標を金額換算のビジネス価値に翻訳して示せる（「適合率99.2%」ではなく「不正取引をX円分防止した」）。効果測定レポートをROI前提と比較できる。 | H14: 事業レビューを設計・主導し、反証と不確実性を含めて次期投資・継続／停止を判断できる。B2B販売契約の更新は該当時だけ外部契約台帳で別に扱う。 | I14: 効果測定レポート、月次／四半期パフォーマンスレポート、ビジネス価値貢献レポート、QBR資料、次期提案 | J14: B4-17,B5-21,B6-09 | K14: SK11 | L14: U02 | M14: 受託版の行動基準を自社事業向けに再編。関連タスクは本版B-IDで再定義。
... A84: S081 | B84: ビジネス | C84: 継続ガバナンス | D84: リスク比例の投資・公開・継続・変更判断 | E84: 事業性と安全性を別軸で確認し、継続・拡大・転換・停止と再Gateを運用する。 | F84: 判断のOwner、禁止条件、証拠を説明できる。 | G84: 残存リスクに期限・責任者を付け、重大変更を要件・設計・評価へ戻せる。 | H84: 組織の投資ポートフォリオと危害を整合させ、事業都合の品質上書きを防げる。 | I84: 投資・Release・例外・継続判断記録 | J84: B0-16,B0-18,B1-10,B1-17,B1-19,B2-19,B2-20,B4-13,B4-14,B5-10,B5-12,B5-17,B5-20,B5-21,B5-22,B6-10 | K84: SK81 | L84: U01,U02 | M84: 受託契約中心の定義を事業投資・プロダクト責任へ明示的に変更。
A85: S082 | B85: 事業・Product | C85: Discovery | D85: 課題発見と需要の反証 | E85: JTBD、利用者・購買者、代替行動を調べ、需要の裏付けと反証を整理する。 | F85: 誘導しない質問で観察を記録できる。 | G85: 行動証拠から課題・優先セグメントを定義し最小実験できる。 | H85: 複数の機会を比較し、探索の停止・転換を主導できる。 | I85: 観察記録・Opportunity Brief | J85: B0-01,B0-03,B0-04,B0-05,B0-12,B5-13 | L85: U01 | M85: 添付提案を実行・スキル評価に具体化。U03は本資料の追加設計。
A86: S083 | B86: 事業・Product | C86: 収益 | D86: 価格・支払意思・パッケージ | E86: 価格単位、無償枠、支払意思、差別的影響を検証し提供条件へ落とす。 | F86: 利用者と支払者、料金単位を区別できる。 | G86: 価格仮説とテストを設計し原価・価値から判断できる。 | H86: 複数顧客群の価格、解約、粗利、誤課金リスクを統合できる。 | I86: 価格実験・提供条件 | J86: B0-09,B1-12,B4-10,B4-16,B5-14 | L86: U01 | M86: 添付提案を実行・スキル評価に具体化。U03は本資料の追加設計。
A87: S084 | B87: 事業・Product | C87: 事業モデル | D87: 収益・価値交換モデル | E87: 売切り、従量、定額、成果型、社内価値の仮説と制約を整理する。 | F87: 収益源と費用・リスクの帰属を説明できる。 | G87: 価値指標と課金指標の不一致を検出できる。 | H87: 市場・パートナー・事業戦略に適合するモデルを選べる。 | I87: Business Model・感度分析 | J87: B0-09 | L87: U01 | M87: 添付提案を実行・スキル評価に具体化。U03は本資料の追加設計。
A88: S085 | B88: 事業・Product | C88: GTM | D88: 市場投入・販売・導入設計 | E88: 獲得経路、購買審査、導入、公開機能、販売資料を実装と接続する。 | F88: ユーザー導入の主要な障壁を記録できる。 | G88: 価格、営業、サポート、Releaseを揃えLaunchできる。 | H88: 異なる市場・地域のGTMとリスク再審査を設計できる。 | I88: Launch計画・販売資料・導入実績 | J88: B0-03,B0-14,B1-11,B3-20,B4-16,B5-22 | L88: U01 | M88: 添付提案を実行・スキル評価に具体化。U03は本資料の追加設計。
A89: S086 | B89: 事業・Product | C89: Growth | D89: ファネル・コホート・継続改善 | E89: 利用開始、価値到達、継続、解約を同じ定義で観測し改善する。 | F89: 登録数と利用価値・継続率を区別できる。 | G89: コホートと分母を定義し失敗箇所を分析できる。 | H89: 長期価値と安全guardrailを満たすGrowthを設計できる。 | I89: ファネル・継続分析・実験 | J89: B0-14,B5-02,B5-14 | L89: U01 | M89: 添付提案を実行・スキル評価に具体化。U03は本資料の追加設計。
A90: S087 | B90: 事業・Product | C90: 実験 | D90: 仮説・実験・反証・意思決定 | E90: 実験の成功・中止条件を先に定め、学びを次の投資へ接続する。 | F90: 仮説と検証観測を分けられる。 | G90: 交絡、期間、サンプル、費用を考慮して実験できる。 | H90: 複数実験の探索価値と誤判定コストを統合できる。 | I90: 実験台帳・判断・学習ログ | J90: B0-11,B0-12,B0-17,B1-03,B1-15,B4-15,B5-13,B5-14 | L90: U01 | M90: 添付提案を実行・スキル評価に具体化。U03は本資料の追加設計。
A91: S088 | B91: 組織・Delivery | C91: 体制 | D91: スキルギャップ・兼務・要員設計 | E91: 必要能力、稼働、独立性を分け、採用・育成・外部活用を選ぶ。 | F91: 必要スキルと人の保有能力を区別できる。 | G91: 行動証拠で不足を判定し担当・期限を設けられる。 | H91: 単独依存・利益相反・レビュー能力を含む体制を設計できる。 | I91: 能力評価・要員・育成計画 | J91: B0-15,B1-16,B5-19 | L91: U01 | M91: 添付提案を実行・スキル評価に具体化。U03は本資料の追加設計。
A92: S089 | B92: 事業運営 | C92: CS | D92: 導入・顧客成功・救済 | E92: 利用定着、問い合わせ、誤回答、返金、苦情を継続改善へつなぐ。 | F92: 通常質問と危害・事故を分類できる。 | G92: 導入・エスカレーション・救済手順を運用できる。 | H92: サービス拡大時の支援容量と品質、安全を設計できる。 | I92: CS記録・導入指標・救済記録 | J92: B0-14,B1-11,B3-20,B4-12,B4-16,B4-17,B5-07,B6-02 | L92: U01 | M92: 添付提案を実行・スキル評価に具体化。U03は本資料の追加設計。
A93: S090 | B93: 事業・分析 | C93: Analytics | D93: 価値指標・計測・意思決定分析 | E93: KPIの分母、期間、イベント、欠測、コホートを統一する。 | F93: イベントと事業指標の関係を説明できる。 | G93: プライバシーを守り計測・集計・検証できる。 | H93: 指標の歪み、交絡、Goodhart化を検出し計測体系を改善できる。 | I93: KPI定義・計測試験・意思決定 | J93: B1-01,B1-18,B5-02,B5-14 | L93: U01 | M93: 添付提案を実行・スキル評価に具体化。U03は本資料の追加設計。
A94: S091 | B94: エンジニアリング | C94: 収益基盤 | D94: 利用量計測・課金・返金 | E94: 利用量と価格を結び、二重請求・過大請求・無料枠悪用を防ぐ。 | F94: 課金イベントと成功条件を説明できる。 | G94: 冪等な課金、照合、上限、取消を実装できる。 | H94: 複数料金体系・遡及修正・事故時救済を設計できる。 | I94: 課金仕様・照合テスト・精算 | J94: B1-12,B2-09,B2-17,B3-14,B4-10,B5-06 | L94: U03 | M94: 添付提案を実行・スキル評価に具体化。U03は本資料の追加設計。
A95: S092 | B95: 事業運営 | C95: 調達 | D95: Build/Buy/Partnerと調達判断 | E95: 外部依存の総費用、権利、供給継続、切替を比較する。 | F95: 比較項目と情報不足を整理できる。 | G95: ベンダー評価・受入条件・退出計画を作れる。 | H95: 調達集中・ロックインと内製能力を戦略的に調整できる。 | I95: 調達ADR・契約・代替計画 | J95: B1-13 | L95: U01 | M95: 添付提案を実行・スキル評価に具体化。U03は本資料の追加設計。
A96: S093 | B96: 事業・FinOps | C96: 単位経済性 | D96: 成功単位原価・限界利益・費用境界 | E96: AI、検索、再試行、手動介入、CSを含む成功当たり原価を計測する。 | F96: 費用、粗利、キャッシュ、能力余力を区別できる。 | G96: 料金・成功率・利用量の感度を計算できる。 | H96: 利益改善と品質劣化のtrade-offを統合し投資判断できる。 | I96: cost/success・収支・感度分析 | J96: B0-09,B0-10,B1-12,B1-18,B2-17,B3-14,B3-22,B4-10,B5-06 | L96: U01,W08 | M96: 添付提案を実行・スキル評価に具体化。U03は本資料の追加設計。
... A109: S106 | B109: 組織・Delivery | C109: Flow | D109: レビュー容量・WIP・品質調整済み速度 | E109: 実装速度でなく価値提供の待ち・手戻り・品質を含む流れを改善する。 | F109: 生成量と完了価値、工数とリードタイムを区別できる。 | G109: レビュー待ち・障害・再作業を計測しWIPを調整できる。 | H109: 同等品質での投資効果と組織ボトルネックを改善できる。 | I109: Flow指標・能力計画・E2E比較 | J109: B1-16,B5-19 | L109: U01,W07,W08 | M109: 添付提案を実行・スキル評価に具体化。U03は本資料の追加設計。

Sheet 08_タスク×ロール×スキル
A1: タスク×ロール×スキル｜必要能力の割当
A2: 1行=標準Task×Skill（候補Role）。案件のTask×Role×Skill×Personは35で確定。全員に全Skillを要求しない。
A3: Task ID | B3: タスク名（参照） | C3: 実施R | D3: 承認A | E3: Skill ID | F3: スキル名（参照） | G3: 必要Lv | H3: 確認する証拠 | I3: 割当方針
A4: B0-01 | B4: =IF(COUNTIF('02_工程タスク'!$A$4:$A$135,A4)<>1,"参照ID不正",IF(INDEX('02_工程タスク'!$D$4:$D$135,MATCH(A4,'02_工程タスク'!$A$4:$A$135,0))="","",INDEX('02_工程タスク'!$D$4:$D$135,MATCH(A4,'02_工程タスク'!$A$4:$A$135,0)))) -> 探索責任者・初期枠の設定 | C4: =IF(COUNTIF('02_工程タスク'!$A$4:$A$135,A4)<>1,"参照ID不正",IF(INDEX('02_工程タスク'!$G$4:$G$135,MATCH(A4,'02_工程タスク'!$A$4:$A$135,0))="","",INDEX('02_工程タスク'!$G$4:$G$135,MATCH(A4,'02_工程タスク'!$A$4:$A$135,0)))) -> R02, R03 | D4: =IF(COUNTIF('02_工程タスク'!$A$4:$A$135,A4)<>1,"参照ID不正",IF(INDEX('02_工程タスク'!$H$4:$H$135,MATCH(A4,'02_工程タスク'!$A$4:$A$135,0))="","",INDEX('02_工程タスク'!$H$4:$H$135,MATCH(A4,'02_工程タスク'!$A$4:$A$135,0)))) -> R01 | E4: S001 | F4: =IF(COUNTIF('07_スキル辞書'!$A$4:$A$109,E4)<>1,"参照ID不正",IF(INDEX('07_スキル辞書'!$D$4:$D$109,MATCH(E4,'07_スキル辞書'!$A$4:$A$109,0))="","",INDEX('07_スキル辞書'!$D$4:$D$109,MATCH(E4,'07_スキル辞書'!$A$4:$A$109,0)))) -> 七工程と事業投資・公開ゲートの運用 | G4: 2 | H4: =IF(COUNTIF('07_スキル辞書'!$A$4:$A$109,E4)<>1,"参照ID不正",IF(INDEX('07_スキル辞書'!$I$4:$I$109,MATCH(E4,'07_スキル辞書'!$A$4:$A$109,0))="","",INDEX('07_スキル辞書'!$I$4:$I$109,MATCH(E4,'07_スキル辞書'!$A$4:$A$109,0)))) -> G0〜G5判断記録・再Gate計画 | I4: 役割ごとに必要な組合せを06/28で担当者へ割当。全員に全Skillを要求しない。
A5: B0-01 | B5: =IF(COUNTIF('02_工程タスク'!$A$4:$A$135,A5)<>1,"参照ID不正",IF(INDEX('02_工程タスク'!$D$4:$D$135,MATCH(A5,'02_工程タスク'!$A$4:$A$135,0))="","",INDEX('02_工程タスク'!$D$4:$D$135,MATCH(A5,'02_工程タスク'!$A$4:$A$135,0)))) -> 探索責任者・初期枠の設定 | C5: =IF(COUNTIF('02_工程タスク'!$A$4:$A$135,A5)<>1,"参照ID不正",IF(INDEX('02_工程タスク'!$G$4:$G$135,MATCH(A5,'02_工程タスク'!$A$4:$A$135,0))="","",INDEX('02_工程タスク'!$G$4:$G$135,MATCH(A5,'02_工程タスク'!$A$4:$A$135,0)))) -> R02, R03 | D5: =IF(COUNTIF('02_工程タスク'!$A$4:$A$135,A5)<>1,"参照ID不正",IF(INDEX('02_工程タスク'!$H$4:$H$135,MATCH(A5,'02_工程タスク'!$A$4:$A$135,0))="","",INDEX('02_工程タスク'!$H$4:$H$135,MATCH(A5,'02_工程タスク'!$A$4:$A$135,0)))) -> R01 | E5: S006 | F5: =IF(COUNTIF('07_スキル辞書'!$A$4:$A$109,E5)<>1,"参照ID不正",IF(INDEX('07_スキル辞書'!$D$4:$D$109,MATCH(E5,'07_スキル辞書'!$A$4:$A$109,0))="","",INDEX('07_スキル辞書'!$D$4:$D$109,MATCH(E5,'07_スキル辞書'!$A$4:$A$109,0)))) -> ステークホルダー分析とRACI運用 | G5: 2 | H5: =IF(COUNTIF('07_スキル辞書'!$A$4:$A$109,E5)<>1,"参照ID不正",IF(INDEX('07_スキル辞書'!$I$4:$I$109,MATCH(E5,'07_スキル辞書'!$A$4:$A$109,0))="","",INDEX('07_スキル辞書'!$I$4:$I$109,MATCH(E5,'07_スキル辞書'!$A$4:$A$109,0)))) -> ステークホルダーマップ、RACIチャート v1、RACIチャート v2、利用部門の責任・権限一覧、運用体制図 | I5: 役割ごとに必要な組合せを06/28で担当者へ割当。全員に全Skillを要求しない。
A6: B0-01 | B6: =IF(COUNTIF('02_工程タスク'!$A$4:$A$135,A6)<>1,"参照ID不正",IF(INDEX('02_工程タスク'!$D$4:$D$135,MATCH(A6,'02_工程タスク'!$A$4:$A$135,0))="","",INDEX('02_工程タスク'!$D$4:$D$135,MATCH(A6,'02_工程タスク'!$A$4:$A$135,0)))) -> 探索責任者・初期枠の設定 | C6: =IF(COUNTIF('02_工程タスク'!$A$4:$A$135,A6)<>1,"参照ID不正",IF(INDEX('02_工程タスク'!$G$4:$G$135,MATCH(A6,'02_工程タスク'!$A$4:$A$135,0))="","",INDEX('02_工程タスク'!$G$4:$G$135,MATCH(A6,'02_工程タスク'!$A$4:$A$135,0)))) -> R02, R03 | D6: =IF(COUNTIF('02_工程タスク'!$A$4:$A$135,A6)<>1,"参照ID不正",IF(INDEX('02_工程タスク'!$H$4:$H$135,MATCH(A6,'02_工程タスク'!$A$4:$A$135,0))="","",INDEX('02_工程タスク'!$H$4:$H$135,MATCH(A6,'02_工程タスク'!$A$4:$A$135,0)))) -> R01 | E6: S082 | F6: =IF(COUNTIF('07_スキル辞書'!$A$4:$A$109,E6)<>1,"参照ID不正",IF(INDEX('07_スキル辞書'!$D$4:$D$109,MATCH(E6,'07_スキル辞書'!$A$4:$A$109,0))="","",INDEX('07_スキル辞書'!$D$4:$D$109,MATCH(E6,'07_スキル辞書'!$A$4:$A$109,0)))) -> 課題発見と需要の反証 | G6: 2 | H6: =IF(COUNTIF('07_スキル辞書'!$A$4:$A$109,E6)<>1,"参照ID不正",IF(INDEX('07_スキル辞書'!$I$4:$I$109,MATCH(E6,'07_スキル辞書'!$A$4:$A$109,0))="","",INDEX('07_スキル辞書'!$I$4:$I$109,MATCH(E6,'07_スキル辞書'!$A$4:$A$109,0)))) -> 観察記録・Opportunity Brief | I6: 役割ごとに必要な組合せを06/28で担当者へ割当。全員に全Skillを要求しない。
A7: B0-02 | B7: =IF(COUNTIF('02_工程タスク'!$A$4:$A$135,A7)<>1,"参照ID不正",IF(INDEX('02_工程タスク'!$D$4:$D$135,MATCH(A7,'02_工程タスク'!$A$4:$A$135,0))="","",INDEX('02_工程タスク'!$D$4:$D$135,MATCH(A7,'02_工程タスク'!$A$4:$A$135,0)))) -> 市場・競合・規制候補の調査 | C7: =IF(COUNTIF('02_工程タスク'!$A$4:$A$135,A7)<>1,"参照ID不正",IF(INDEX('02_工程タスク'!$G$4:$G$135,MATCH(A7,'02_工程タスク'!$A$4:$A$135,0))="","",INDEX('02_工程タスク'!$G$4:$G$135,MATCH(A7,'02_工程タスク'!$A$4:$A$135,0)))) -> R02, R04, R16 | D7: =IF(COUNTIF('02_工程タスク'!$A$4:$A$135,A7)<>1,"参照ID不正",IF(INDEX('02_工程タスク'!$H$4:$H$135,MATCH(A7,'02_工程タスク'!$A$4:$A$135,0))="","",INDEX('02_工程タスク'!$H$4:$H$135,MATCH(A7,'02_工程タスク'!$A$4:$A$135,0)))) -> R02 | E7: S002 | F7: =IF(COUNTIF('07_スキル辞書'!$A$4:$A$109,E7)<>1,"参照ID不正",IF(INDEX('07_スキル辞書'!$D$4:$D$109,MATCH(E7,'07_スキル辞書'!$A$4:$A$109,0))="","",INDEX('07_スキル辞書'!$D$4:$D$109,MATCH(E7,'07_スキル辞書'!$A$4:$A$109,0)))) -> AIガバナンスと関連法規の適用 | G7: 2 | H7: =IF(COUNTIF('07_スキル辞書'!$A$4:$A$109,E7)<>1,"参照ID不正",IF(INDEX('07_スキル辞書'!$I$4:$I$109,MATCH(E7,'07_スキル辞書'!$A$4:$A$109,0))="","",INDEX('07_スキル辞書'!$I$4:$I$109,MATCH(E7,'07_スキル辞書'!$A$4:$A$109,0)))) -> リサーチ資料、リスク管理台帳 v1、責任あるAI評価レポート、モデルカード、AIインシデント対応手順書 | I7: 役割ごとに必要な組合せを06/28で担当者へ割当。全員に全Skillを要求しない。
A8: B0-02 | B8: =IF(COUNTIF('02_工程タスク'!$A$4:$A$135,A8)<>1,"参照ID不正",IF(INDEX('02_工程タスク'!$D$4:$D$135,MATCH(A8,'02_工程タスク'!$A$4:$A$135,0))="","",INDEX('02_工程タスク'!$D$4:$D$135,MATCH(A8,'02_工程タスク'!$A$4:$A$135,0)))) -> 市場・競合・規制候補の調査 | C8: =IF(COUNTIF('02_工程タスク'!$A$4:$A$135,A8)<>1,"参照ID不正",IF(INDEX('02_工程タスク'!$G$4:$G$135,MATCH(A8,'02_工程タスク'!$A$4:$A$135,0))="","",INDEX('02_工程タスク'!$G$4:$G$135,MATCH(A8,'02_工程タスク'!$A$4:$A$135,0)))) -> R02, R04, R16 | D8: =IF(COUNTIF('02_工程タスク'!$A$4:$A$135,A8)<>1,"参照ID不正",IF(INDEX('02_工程タスク'!$H$4:$H$135,MATCH(A8,'02_工程タスク'!$A$4:$A$135,0))="","",INDEX('02_工程タスク'!$H$4:$H$135,MATCH(A8,'02_工程タスク'!$A$4:$A$135,0)))) -> R02 | E8: S007 | F8: =IF(COUNTIF('07_スキル辞書'!$A$4:$A$109,E8)<>1,"参照ID不正",IF(INDEX('07_スキル辞書'!$D$4:$D$109,MATCH(E8,'07_スキル辞書'!$A$4:$A$109,0))="","",INDEX('07_スキル辞書'!$D$4:$D$109,MATCH(E8,'07_スキル辞書'!$A$4:$A$109,0)))) -> ドメイン知識の獲得と活用 | G8: 2 | H8: =IF(COUNTIF('07_スキル辞書'!$A$4:$A$109,E8)<>1,"参照ID不正",IF(INDEX('07_スキル辞書'!$I$4:$I$109,MATCH(E8,'07_スキル辞書'!$A$4:$A$109,0))="","",INDEX('07_スキル辞書'!$I$4:$I$109,MATCH(E8,'07_スキル辞書'!$A$4:$A$109,0)))) -> リサーチ資料、As-Is業務フロー図、業務適合性評価レポート、ヒアリング議事録 | I8: 役割ごとに必要な組合せを06/28で担当者へ割当。全員に全Skillを要求しない。
A9: B0-02 | B9: =IF(COUNTIF('02_工程タスク'!$A$4:$A$135,A9)<>1,"参照ID不正",IF(INDEX('02_工程タスク'!$D$4:$D$135,MATCH(A9,'02_工程タスク'!$A$4:$A$135,0))="","",INDEX('02_工程タスク'!$D$4:$D$135,MATCH(A9,'02_工程タスク'!$A$4:$A$135,0)))) -> 市場・競合・規制候補の調査 | C9: =IF(COUNTIF('02_工程タスク'!$A$4:$A$135,A9)<>1,"参照ID不正",IF(INDEX('02_工程タスク'!$G$4:$G$135,MATCH(A9,'02_工程タスク'!$A$4:$A$135,0))="","",INDEX('02_工程タスク'!$G$4:$G$135,MATCH(A9,'02_工程タスク'!$A$4:$A$135,0)))) -> R02, R04, R16 | D9: =IF(COUNTIF('02_工程タスク'!$A$4:$A$135,A9)<>1,"参照ID不正",IF(INDEX('02_工程タスク'!$H$4:$H$135,MATCH(A9,'02_工程タスク'!$A$4:$A$135,0))="","",INDEX('02_工程タスク'!$H$4:$H$135,MATCH(A9,'02_工程タスク'!$A$4:$A$135,0)))) -> R02 | E9: S008 | F9: =IF(COUNTIF('07_スキル辞書'!$A$4:$A$109,E9)<>1,"参照ID不正",IF(INDEX('07_スキル辞書'!$D$4:$D$109,MATCH(E9,'07_スキル辞書'!$A$4:$A$109,0))="","",INDEX('07_スキル辞書'!$D$4:$D$109,MATCH(E9,'07_スキル辞書'!$A$4:$A$109,0)))) -> 事業戦略理解とビジネス分析フレームワークの活用 | G9: 2 | H9: =IF(COUNTIF('07_スキル辞書'!$A$4:$A$109,E9)<>1,"参照ID不正",IF(INDEX('07_スキル辞書'!$I$4:$I$109,MATCH(E9,'07_スキル辞書'!$A$4:$A$109,0))="","",INDEX('07_スキル辞書'!$I$4:$I$109,MATCH(E9,'07_スキル辞書'!$A$4:$A$109,0)))) -> リサーチ資料、実現可能性評価レポート、QBR資料、次期提案、提案書 | I9: 役割ごとに必要な組合せを06/28で担当者へ割当。全員に全Skillを要求しない。
A10: B0-03 | B10: =IF(COUNTIF('02_工程タスク'!$A$4:$A$135,A10)<>1,"参照ID不正",IF(INDEX('02_工程タスク'!$D$4:$D$135,MATCH(A10,'02_工程タスク'!$A$4:$A$135,0))="","",INDEX('02_工程タスク'!$D$4:$D$135,MATCH(A10,'02_工程タスク'!$A$4:$A$135,0)))) -> 利用者・購買者の仮説分解 | C10: =IF(COUNTIF('02_工程タスク'!$A$4:$A$135,A10)<>1,"参照ID不正",IF(INDEX('02_工程タスク'!$G$4:$G$135,MATCH(A10,'02_工程タスク'!$A$4:$A$135,0))="","",INDEX('02_工程タスク'!$G$4:$G$135,MATCH(A10,'02_工程タスク'!$A$4:$A$135,0)))) -> R02, R05 | D10: =IF(COUNTIF('02_工程タスク'!$A$4:$A$135,A10)<>1,"参照ID不正",IF(INDEX('02_工程タスク'!$H$4:$H$135,MATCH(A10,'02_工程タスク'!$A$4:$A$135,0))="","",INDEX('02_工程タスク'!$H$4:$H$135,MATCH(A10,'02_工程タスク'!$A$4:$A$135,0)))) -> R02 | E10: S004 | F10: =IF(COUNTIF('07_スキル辞書'!$A$4:$A$109,E10)<>1,"参照ID不正",IF(INDEX('07_スキル辞書'!$D$4:$D$109,MATCH(E10,'07_スキル辞書'!$A$4:$A$109,0))="","",INDEX('07_スキル辞書'!$D$4:$D$109,MATCH(E10,'07_スキル辞書'!$A$4:$A$109,0)))) -> ヒアリングと課題定義 | G10: 2 | H10: =IF(COUNTIF('07_スキル辞書'!$A$4:$A$109,E10)<>1,"参照ID不正",IF(INDEX('07_スキル辞書'!$I$4:$I$109,MATCH(E10,'07_スキル辞書'!$A$4:$A$109,0))="","",INDEX('07_スキル辞書'!$I$4:$I$109,MATCH(E10,'07_スキル辞書'!$A$4:$A$109,0)))) -> ヒアリングリスト、ヒアリング記録、課題リスト（優先順位付き）、ヒアリング議事録、課題定義書 | I10: 役割ごとに必要な組合せを06/28で担当者へ割当。全員に全Skillを要求しない。
A11: B0-03 | B11: =IF(COUNTIF('02_工程タスク'!$A$4:$A$135,A11)<>1,"参照ID不正",IF(INDEX('02_工程タスク'!$D$4:$D$135,MATCH(A11,'02_工程タスク'!$A$4:$A$135,0))="","",INDEX('02_工程タスク'!$D$4:$D$135,MATCH(A11,'02_工程タスク'!$A$4:$A$135,0)))) -> 利用者・購買者の仮説分解 | C11: =IF(COUNTIF('02_工程タスク'!$A$4:$A$135,A11)<>1,"参照ID不正",IF(INDEX('02_工程タスク'!$G$4:$G$135,MATCH(A11,'02_工程タスク'!$A$4:$A$135,0))="","",INDEX('02_工程タスク'!$G$4:$G$135,MATCH(A11,'02_工程タスク'!$A$4:$A$135,0)))) -> R02, R05 | D11: =IF(COUNTIF('02_工程タスク'!$A$4:$A$135,A11)<>1,"参照ID不正",IF(INDEX('02_工程タスク'!$H$4:$H$135,MATCH(A11,'02_工程タスク'!$A$4:$A$135,0))="","",INDEX('02_工程タスク'!$H$4:$H$135,MATCH(A11,'02_工程タスク'!$A$4:$A$135,0)))) -> R02 | E11: S082 | F11: =IF(COUNTIF('07_スキル辞書'!$A$4:$A$109,E11)<>1,"参照ID不正",IF(INDEX('07_スキル辞書'!$D$4:$D$109,MATCH(E11,'07_スキル辞書'!$A$4:$A$109,0))="","",INDEX('07_スキル辞書'!$D$4:$D$109,MATCH(E11,'07_スキル辞書'!$A$4:$A$109,0)))) -> 課題発見と需要の反証 | G11: 2 | H11: =IF(COUNTIF('07_スキル辞書'!$A$4:$A$109,E11)<>1,"参照ID不正",IF(INDEX('07_スキル辞書'!$I$4:$I$109,MATCH(E11,'07_スキル辞書'!$A$4:$A$109,0))="","",INDEX('07_スキル辞書'!$I$4:$I$109,MATCH(E11,'07_スキル辞書'!$A$4:$A$109,0)))) -> 観察記録・Opportunity Brief | I11: 役割ごとに必要な組合せを06/28で担当者へ割当。全員に全Skillを要求しない。
A12: B0-03 | B12: =IF(COUNTIF('02_工程タスク'!$A$4:$A$135,A12)<>1,"参照ID不正",IF(INDEX('02_工程タスク'!$D$4:$D$135,MATCH(A12,'02_工程タスク'!$A$4:$A$135,0))="","",INDEX('02_工程タスク'!$D$4:$D$135,MATCH(A12,'02_工程タスク'!$A$4:$A$135,0)))) -> 利用者・購買者の仮説分解 | C12: =IF(COUNTIF('02_工程タスク'!$A$4:$A$135,A12)<>1,"参照ID不正",IF(INDEX('02_工程タスク'!$G$4:$G$135,MATCH(A12,'02_工程タスク'!$A$4:$A$135,0))="","",INDEX('02_工程タスク'!$G$4:$G$135,MATCH(A12,'02_工程タスク'!$A$4:$A$135,0)))) -> R02, R05 | D12: =IF(COUNTIF('02_工程タスク'!$A$4:$A$135,A12)<>1,"参照ID不正",IF(INDEX('02_工程タスク'!$H$4:$H$135,MATCH(A12,'02_工程タスク'!$A$4:$A$135,0))="","",INDEX('02_工程タスク'!$H$4:$H$135,MATCH(A12,'02_工程タスク'!$A$4:$A$135,0)))) -> R02 | E12: S085 | F12: =IF(COUNTIF('07_スキル辞書'!$A$4:$A$109,E12)<>1,"参照ID不正",IF(INDEX('07_スキル辞書'!$D$4:$D$109,MATCH(E12,'07_スキル辞書'!$A$4:$A$109,0))="","",INDEX('07_スキル辞書'!$D$4:$D$109,MATCH(E12,'07_スキル辞書'!$A$4:$A$109,0)))) -> 市場投入・販売・導入設計 | G12: 2 | H12: =IF(COUNTIF('07_スキル辞書'!$A$4:$A$109,E12)<>1,"参照ID不正",IF(INDEX('07_スキル辞書'!$I$4:$I$109,MATCH(E12,'07_スキル辞書'!$A$4:$A$109,0))="","",INDEX('07_スキル辞書'!$I$4:$I$109,MATCH(E12,'07_スキル辞書'!$A$4:$A$109,0)))) -> Launch計画・販売資料・導入実績 | I12: 役割ごとに必要な組合せを06/28で担当者へ割当。全員に全Skillを要求しない。
A13: B0-04 | B13: =IF(COUNTIF('02_工程タスク'!$A$4:$A$135,A13)<>1,"参照ID不正",IF(INDEX('02_工程タスク'!$D$4:$D$135,MATCH(A13,'02_工程タスク'!$A$4:$A$135,0))="","",INDEX('02_工程タスク'!$D$4:$D$135,MATCH(A13,'02_工程タスク'!$A$4:$A$135,0)))) -> インタビュー・現場観察 | C13: =IF(COUNTIF('02_工程タスク'!$A$4:$A$135,A13)<>1,"参照ID不正",IF(INDEX('02_工程タスク'!$G$4:$G$135,MATCH(A13,'02_工程タスク'!$A$4:$A$135,0))="","",INDEX('02_工程タスク'!$G$4:$G$135,MATCH(A13,'02_工程タスク'!$A$4:$A$135,0)))) -> R05, R04 | D13: =IF(COUNTIF('02_工程タスク'!$A$4:$A$135,A13)<>1,"参照ID不正",IF(INDEX('02_工程タスク'!$H$4:$H$135,MATCH(A13,'02_工程タスク'!$A$4:$A$135,0))="","",INDEX('02_工程タスク'!$H$4:$H$135,MATCH(A13,'02_工程タスク'!$A$4:$A$135,0)))) -> R02 | E13: S004 | F13: =IF(COUNTIF('07_スキル辞書'!$A$4:$A$109,E13)<>1,"参照ID不正",IF(INDEX('07_スキル辞書'!$D$4:$D$109,MATCH(E13,'07_スキル辞書'!$A$4:$A$109,0))="","",INDEX('07_スキル辞書'!$D$4:$D$109,MATCH(E13,'07_スキル辞書'!$A$4:$A$109,0)))) -> ヒアリングと課題定義 | G13: 2 | H13: =IF(COUNTIF('07_スキル辞書'!$A$4:$A$109,E13)<>1,"参照ID不正",IF(INDEX('07_スキル辞書'!$I$4:$I$109,MATCH(E13,'07_スキル辞書'!$A$4:$A$109,0))="","",INDEX('07_スキル辞書'!$I$4:$I$109,MATCH(E13,'07_スキル辞書'!$A$4:$A$109,0)))) -> ヒアリングリスト、ヒアリング記録、課題リスト（優先順位付き）、ヒアリング議事録、課題定義書 | I13: 役割ごとに必要な組合せを06/28で担当者へ割当。全員に全Skillを要求しない。
A14: B0-04 | B14: =IF(COUNTIF('02_工程タスク'!$A$4:$A$135,A14)<>1,"参照ID不正",IF(INDEX('02_工程タスク'!$D$4:$D$135,MATCH(A14,'02_工程タスク'!$A$4:$A$135,0))="","",INDEX('02_工程タスク'!$D$4:$D$135,MATCH(A14,'02_工程タスク'!$A$4:$A$135,0)))) -> インタビュー・現場観察 | C14: =IF(COUNTIF('02_工程タスク'!$A$4:$A$135,A14)<>1,"参照ID不正",IF(INDEX('02_工程タスク'!$G$4:$G$135,MATCH(A14,'02_工程タスク'!$A$4:$A$135,0))="","",INDEX('02_工程タスク'!$G$4:$G$135,MATCH(A14,'02_工程タスク'!$A$4:$A$135,0)))) -> R05, R04 | D14: =IF(COUNTIF('02_工程タスク'!$A$4:$A$135,A14)<>1,"参照ID不正",IF(INDEX('02_工程タスク'!$H$4:$H$135,MATCH(A14,'02_工程タスク'!$A$4:$A$135,0))="","",INDEX('02_工程タスク'!$H$4:$H$135,MATCH(A14,'02_工程タスク'!$A$4:$A$135,0)))) -> R02 | E14: S019 | F14: =IF(COUNTIF('07_スキル辞書'!$A$4:$A$109,E14)<>1,"参照ID不正",IF(INDEX('07_スキル辞書'!$D$4:$D$109,MATCH(E14,'07_スキル辞書'!$A$4:$A$109,0))="","",INDEX('07_スキル辞書'!$D$4:$D$109,MATCH(E14,'07_スキル辞書'!$A$4:$A$109,0)))) -> 業務フロー分析とHITL設計 | G14: 2 | H14: =IF(COUNTIF('07_スキル辞書'!$A$4:$A$109,E14)<>1,"参照ID不正",IF(INDEX('07_スキル辞書'!$I$4:$I$109,MATCH(E14,'07_スキル辞書'!$A$4:$A$109,0))="","",INDEX('07_スキル辞書'!$I$4:$I$109,MATCH(E14,'07_スキル辞書'!$A$4:$A$109,0)))) -> As-Is業務フロー図、To-Be業務フロー図、段階展開計画 | I14: 役割ごとに必要な組合せを06/28で担当者へ割当。全員に全Skillを要求しない。
A15: B0-04 | B15: =IF(COUNTIF('02_工程タスク'!$A$4:$A$135,A15)<>1,"参照ID不正",IF(INDEX('02_工程タスク'!$D$4:$D$135,MATCH(A15,'02_工程タスク'!$A$4:$A$135,0))="","",INDEX('02_工程タスク'!$D$4:$D$135,MATCH(A15,'02_工程タスク'!$A$4:$A$135,0)))) -> インタビュー・現場観察 | C15: =IF(COUNTIF('02_工程タスク'!$A$4:$A$135,A15)<>1,"参照ID不正",IF(INDEX('02_工程タスク'!$G$4:$G$135,MATCH(A15,'02_工程タスク'!$A$4:$A$135,0))="","",INDEX('02_工程タスク'!$G$4:$G$135,MATCH(A15,'02_工程タスク'!$A$4:$A$135,0)))) -> R05, R04 | D15: =IF(COUNTIF('02_工程タスク'!$A$4:$A$135,A15)<>1,"参照ID不正",IF(INDEX('02_工程タスク'!$H$4:$H$135,MATCH(A15,'02_工程タスク'!$A$4:$A$135,0))="","",INDEX('02_工程タスク'!$H$4:$H$135,MATCH(A15,'02_工程タスク'!$A$4:$A$135,0)))) -> R02 | E15: S082 | F15: =IF(COUNTIF('07_スキル辞書'!$A$4:$A$109,E15)<>1,"参照ID不正",IF(INDEX('07_スキル辞書'!$D$4:$D$109,MATCH(E15,'07_スキル辞書'!$A$4:$A$109,0))="","",INDEX('07_スキル辞書'!$D$4:$D$109,MATCH(E15,'07_スキル辞書'!$A$4:$A$109,0)))) -> 課題発見と需要の反証 | G15: 2 | H15: =IF(COUNTIF('07_スキル辞書'!$A$4:$A$109,E15)<>1,"参照ID不正",IF(INDEX('07_スキル辞書'!$I$4:$I$109,MATCH(E15,'07_スキル辞書'!$A$4:$A$109,0))="","",INDEX('07_スキル辞書'!$I$4:$I$109,MATCH(E15,'07_スキル辞書'!$A$4:$A$109,0)))) -> 観察記録・Opportunity Brief | I15: 役割ごとに必要な組合せを06/28で担当者へ割当。全員に全Skillを要求しない。
... A430: B6-11 | B430: =IF(COUNTIF('02_工程タスク'!$A$4:$A$135,A430)<>1,"参照ID不正",IF(INDEX('02_工程タスク'!$D$4:$D$135,MATCH(A430,'02_工程タスク'!$A$4:$A$135,0))="","",INDEX('02_工程タスク'!$D$4:$D$135,MATCH(A430,'02_工程タスク'!$A$4:$A$135,0)))) -> 保持期限到来・残存請求の追跡 | C430: =IF(COUNTIF('02_工程タスク'!$A$4:$A$135,A430)<>1,"参照ID不正",IF(INDEX('02_工程タスク'!$G$4:$G$135,MATCH(A430,'02_工程タスク'!$A$4:$A$135,0))="","",INDEX('02_工程タスク'!$G$4:$G$135,MATCH(A430,'02_工程タスク'!$A$4:$A$135,0)))) -> R18, R10, R15 | D430: =IF(COUNTIF('02_工程タスク'!$A$4:$A$135,A430)<>1,"参照ID不正",IF(INDEX('02_工程タスク'!$H$4:$H$135,MATCH(A430,'02_工程タスク'!$A$4:$A$135,0))="","",INDEX('02_工程タスク'!$H$4:$H$135,MATCH(A430,'02_工程タスク'!$A$4:$A$135,0)))) -> R18 | E430: S103 | F430: =IF(COUNTIF('07_スキル辞書'!$A$4:$A$109,E430)<>1,"参照ID不正",IF(INDEX('07_スキル辞書'!$D$4:$D$109,MATCH(E430,'07_スキル辞書'!$A$4:$A$109,0))="","",INDEX('07_スキル辞書'!$D$4:$D$109,MATCH(E430,'07_スキル辞書'!$A$4:$A$109,0)))) -> 移管・削除・権限失効・請求終了 | G430: 2 | H430: =IF(COUNTIF('07_スキル辞書'!$A$4:$A$109,E430)<>1,"参照ID不正",IF(INDEX('07_スキル辞書'!$I$4:$I$109,MATCH(E430,'07_スキル辞書'!$A$4:$A$109,0))="","",INDEX('07_スキル辞書'!$I$4:$I$109,MATCH(E430,'07_スキル辞書'!$A$4:$A$109,0)))) -> 廃止計画・Deletion/Retention・G5 | I430: 役割ごとに必要な組合せを06/28で担当者へ割当。全員に全Skillを要求しない。

Sheet 09_成果物・正本マップ
A1: 成果物・正本マップ｜証拠の所在を一つにつなぐ
A2: 1行=標準タスクの証拠パッケージ。独立した132文書は不要。Issue/ADR/PR/Eval/Releaseへ版付きリンクで代替できる。
A3: Evidence ID | B3: Task ID | C3: 成果物群 | D3: 推奨する正本 | E3: Ownerロール | F3: 最低限の証拠内容 | G3: 正本URI（入力） | H3: 対象版/hash（入力） | I3: 更新責任者（入力） | J3: 最終確認日（入力） | K3: 承認記録ID（入力）
A4: EV-B0-01 | B4: B0-01 | C4: 探索チャーター・初期予算枠 | D4: Versioned Docs/Issue＋業務台帳 | E4: R01 | F4: 責任者、探索上限、意思決定日、停止権限が記録されている。
A5: EV-B0-02 | B5: B0-02 | C5: 調査メモ・根拠一覧 | D5: Versioned Docs/Issue＋業務台帳 | E5: R02 | F5: 対象市場、利用者、競合、情報の確認日と不確実性がある。
A6: EV-B0-03 | B6: B0-03 | C6: 対象セグメント・調査計画 | D6: Versioned Docs/Issue＋業務台帳 | E6: R02 | F6: 対象者、募集条件、質問、個人情報取扱いが明確。
A7: EV-B0-04 | B7: B0-04 | C7: JTBD・観察記録 | D7: Versioned Docs/Issue＋業務台帳 | E7: R02 | F7: 現行の代替行動と未解決課題を記録し、反証も保存。
